Workbook

Sheet Setup
A1: ⚙️ SETUP — AF_Acciones Template (US Stocks)
A2: Fill the GREEN cells before using. Power Query reads this sheet automatically.
A4: 🔑 FINANCIAL MODELING PREP (FMP) — US Stocks
A5: FMP API Key | C5: ⚠️ Paste your key from financialmodelingprep.com/dashboard
A6: Ticker (US company) | B6: MSFT | C6: E.g.: MSFT · ADBE · AMZN (letters only)
A7: Number of quarters | B7: 4 | C7: Max 5 on the free FMP plan
A9: FOREIGN STOCKS — Manual entry
A10: For foreign tickers there is no free API. Fill Input_Data manually from Yahoo Finance (e.g: ticker.MX)
A12: 📋 HOW TO USE POWER QUERY (US stocks)
A13: 1. Paste your API Key in the green cell B5 of this sheet.
A14: 2. Enter the US ticker in the green cell B6 (e.g.: ADBE).
A15: 3. Go to Data → Queries & Connections → right-click each query → Refresh.
A16: 4. Data will populate automatically in the FMP_Data sheet.
A17: 5. The Input_Data sheet pulls values from FMP_Data via formulas.
A18: 6. Go to Analysis to read the traffic-light signals.
A19: 7. Save the file as: AF_Stocks_TICKER_YYYYMM.xlsx

Sheet FMP_Data
A1: 📡 FMP DATA — Populated automatically by Power Query
A2: DO NOT edit this sheet manually. Use Data → Refresh All to update.
A4: ⚡ POWER QUERY: Data → Get Data → From Web → paste the URL below with your API key. Repeat for Income Statement, Balance Sheet and Cash Flow.
A6: Income Statement (4 quarters): | B6: https://financialmodelingprep.com/stable/income-statement?symbol=TICKER&period=quarter&limit=4&apikey=YOUR_KEY
A7: Balance Sheet (4 quarters): | B7: https://financialmodelingprep.com/stable/balance-sheet-statement?symbol=TICKER&period=quarter&limit=4&apikey=YOUR_KEY
A8: Cash Flow (4 quarters): | B8: https://financialmodelingprep.com/stable/cash-flow-statement?symbol=TICKER&period=quarter&limit=4&apikey=YOUR_KEY
A9: Current Price: | B9: https://financialmodelingprep.com/stable/quote?symbol=TICKER&apikey=YOUR_KEY
A11: Replace TICKER with the symbol (e.g.: ADBE) and YOUR_KEY with your FMP API key. After setting up Power Query, this sheet fills automatically.
A13: Field | B13: Q1 (most recent) | C13: Q2 | D13: Q3 | E13: Q4 | F13: FMP Source
A14: date (quarter end date)
A15: revenue (Total Revenue)
A16: costOfRevenue (Cost of Revenue)
A17: grossProfit (Gross Profit)
A18: operatingExpenses (Operating Expense)
A19: ebitda (EBITDA)
A20: operatingIncome (EBIT / Operating Income)
A21: interestExpense (Interest Expense)
A22: incomeBeforeTax (Pretax Income / EBT)
A23: incomeTaxExpense (Tax Provision)
A24: netIncome (Net Income)
A25: eps (Diluted EPS)
... A37: weightedAverageShsOutDil (Shares Outstanding) [IS]

Sheet Input_Data
A1: 📊 FINANCIAL ANALYSIS — INPUT DATA (Stocks)
A2: 🟡 YELLOW = fill manually · 🔵 BLUE = auto-populated from FMP_Data · Sources: FMP · Yahoo Finance · stockanalysis.com
A3: FIELD | B3: Q1 (most recent) | C3: Q2 | D3: Q3 | E3: Q4 (oldest)
A4: 📅 Quarter end date
A5: GENERAL INFORMATION
A6: Company Name
A7: Ticker / Symbol
A8: Market (US / MX / other)
A9: Share Price (USD or MXN) → Update manually each quarter · stockanalysis.com
A10: Shares Outstanding
A11: 📋 INCOME STATEMENT
A12: Total Revenue / Net Sales
A13: Cost of Revenue (COGS)
A14: Gross Profit
A15: Operating Expense (SG&A + R&D)
... A22: Diluted EPS
A23: Dividend Per Share → Yahoo Finance → Statistics | B23: 0.91 | C23: 0.91 | D23: 0.91 | E23: 0.91
A24: 🏦 BALANCE SHEET
A25: Cash & Cash Equivalents
A26: Total Current Assets
A27: Total Assets
A28: Total Current Liabilities
A29: Total Debt (ST + LT)
A30: Total Liabilities
A31: Common Stock Equity
A32: Book Value Per Share | B32: =IFERROR(B31/B10,"N/D") -> N/D | C32: =IFERROR(C31/C10,"N/D") -> N/D | D32: =IFERROR(D31/D10,"N/D") -> N/D | E32: =IFERROR(E31/E10,"N/D") -> N/D
A33: 💵 CASH FLOW STATEMENT
A34: Operating Cash Flow (CFO)
A35: Capital Expenditure (CAPEX)
A36: Free Cash Flow (FCF = CFO − CAPEX)
A37: Dividends Paid
A38: Share Buybacks
A40: 🔵 BLUE = auto-populated from Power Query (FMP) / or manually · 🟡 YELLOW = fill manually · Share Price always manual · Dividend Per Share manual from Yahoo Finance → Statistics
A41: 📌 File naming: AF_Stocks_TICKER_YYYYMM.xlsx E.g.: AF_Stocks_ADBE_202608.xlsx

Sheet Analysis
A1: 📈 FINANCIAL RATIO ANALYSIS
A2: Ratios calculate automatically from Input_Data. Refresh Power Query to update.
A3: 🟢 GOOD = Healthy 🟡 REVIEW = Caution 🔴 ALERT = Risk ⚪ N/A = No data (Traffic light based on Q1 — most recent quarter)
A4: RATIO | B4: Q1 (latest) | C4: Q2 | D4: Q3 | E4: Q4 (oldest) | F4: INTERPRETATION | G4: SIGNAL
A5: 📅 Reference date | B5: → auto-fills from FMP_Data after Power Query refresh
A6: ── VALUATION (Is the stock expensive?) ──
A7: P/E — Price / Earnings | B7: =IFERROR(Input_Data!B9/Input_Data!B22,"N/D") -> N/D | C7: =IFERROR(Input_Data!C9/Input_Data!C22,"N/D") -> N/D | D7: =IFERROR(Input_Data!D9/Input_Data!D22,"N/D") -> N/D | E7: =IFERROR(Input_Data!E9/Input_Data!E22,"N/D") -> N/D | F7: Years to recoup from earnings. <15x cheap · 15-25x fair · >25x expensive. | G7: =IFERROR(IF(Input_Data!B9=0,"⚪ N/A",IF(Input_Data!B9/Input_Data!B22<15,"🟢 GOOD",IF(Input_Data!B9/Input_Data!B22<25,"🟡 REVIEW","🔴 ALERT"))),"⚪ N/A") -> ⚪ N/A
A8: P/B — Price / Book Value | B8: =IFERROR(Input_Data!B9/Input_Data!B32,"N/D") -> N/D | C8: =IFERROR(Input_Data!C9/Input_Data!C32,"N/D") -> N/D | D8: =IFERROR(Input_Data!D9/Input_Data!D32,"N/D") -> N/D | E8: =IFERROR(Input_Data!E9/Input_Data!E32,"N/D") -> N/D | F8: <1x cheap · 1-3x normal · >3x expensive or intangibles-heavy. | G8: =IFERROR(IF(Input_Data!B9=0,"⚪ N/A",IF(Input_Data!B9/Input_Data!B32<1.5,"🟢 GOOD",IF(Input_Data!B9/Input_Data!B32<3,"🟡 REVIEW","🔴 ALERT"))),"⚪ N/A") -> ⚪ N/A
A9: ── PROFITABILITY (Does it make money?) ──
A10: Gross Margin | B10: =IFERROR(Input_Data!B14/Input_Data!B12,"N/D") -> N/D | C10: =IFERROR(Input_Data!C14/Input_Data!C12,"N/D") -> N/D | D10: =IFERROR(Input_Data!D14/Input_Data!D12,"N/D") -> N/D | E10: =IFERROR(Input_Data!E14/Input_Data!E12,"N/D") -> N/D | F10: Higher = more efficient. Tech >60% · Industrial >30% · Retail ~25%. | G10: =IFERROR(IF(Input_Data!B14/Input_Data!B12>0.4,"🟢 GOOD",IF(Input_Data!B14/Input_Data!B12>0.2,"🟡 REVIEW","🔴 ALERT")),"⚪ N/A") -> ⚪ N/A
A11: Operating Margin (EBIT / Revenue) | B11: =IFERROR(Input_Data!B17/Input_Data!B12,"N/D") -> N/D | C11: =IFERROR(Input_Data!C17/Input_Data!C12,"N/D") -> N/D | D11: =IFERROR(Input_Data!D17/Input_Data!D12,"N/D") -> N/D | E11: =IFERROR(Input_Data!E17/Input_Data!E12,"N/D") -> N/D | F11: Core profitability. >15% good · 8-15% normal · <8% alert. | G11: =IFERROR(IF(Input_Data!B17/Input_Data!B12>0.15,"🟢 GOOD",IF(Input_Data!B17/Input_Data!B12>0.08,"🟡 REVIEW","🔴 ALERT")),"⚪ N/A") -> ⚪ N/A
A12: Net Margin | B12: =IFERROR(Input_Data!B21/Input_Data!B12,"N/D") -> N/D | C12: =IFERROR(Input_Data!C21/Input_Data!C12,"N/D") -> N/D | D12: =IFERROR(Input_Data!D21/Input_Data!D12,"N/D") -> N/D | E12: =IFERROR(Input_Data!E21/Input_Data!E12,"N/D") -> N/D | F12: What remains per $100 of revenue. >10% good · 5-10% normal · <5% alert. | G12: =IFERROR(IF(Input_Data!B21/Input_Data!B12>0.1,"🟢 GOOD",IF(Input_Data!B21/Input_Data!B12>0.05,"🟡 REVIEW","🔴 ALERT")),"⚪ N/A") -> ⚪ N/A
A13: ROE — Return on Equity | B13: =IFERROR(Input_Data!B21/Input_Data!B31,"N/D") -> N/D | C13: =IFERROR(Input_Data!C21/Input_Data!C31,"N/D") -> N/D | D13: =IFERROR(Input_Data!D21/Input_Data!D31,"N/D") -> N/D | E13: =IFERROR(Input_Data!E21/Input_Data!E31,"N/D") -> N/D | F13: Returns on shareholders' capital. >15% excellent · 10-15% good · <10% review. | G13: =IFERROR(IF(Input_Data!B21/Input_Data!B31>0.15,"🟢 GOOD",IF(Input_Data!B21/Input_Data!B31>0.1,"🟡 REVIEW","🔴 ALERT")),"⚪ N/A") -> ⚪ N/A
A14: ── DEBT & SOLVENCY (Can it pay what it owes?) ──
A15: Current Ratio | B15: =IFERROR(Input_Data!B26/Input_Data!B28,"N/D") -> N/D | C15: =IFERROR(Input_Data!C26/Input_Data!C28,"N/D") -> N/D | D15: =IFERROR(Input_Data!D26/Input_Data!D28,"N/D") -> N/D | E15: =IFERROR(Input_Data!E26/Input_Data!E28,"N/D") -> N/D | F15: Short-term liquidity. >2x comfortable · 1-2x normal · <1x risk. | G15: =IFERROR(IF(Input_Data!B26/Input_Data!B28>2,"🟢 GOOD",IF(Input_Data!B26/Input_Data!B28>=1,"🟡 REVIEW","🔴 ALERT")),"⚪ N/A") -> ⚪ N/A
A16: Debt / Equity | B16: =IFERROR(Input_Data!B29/Input_Data!B31,"N/D") -> N/D | C16: =IFERROR(Input_Data!C29/Input_Data!C31,"N/D") -> N/D | D16: =IFERROR(Input_Data!D29/Input_Data!D31,"N/D") -> N/D | E16: =IFERROR(Input_Data!E29/Input_Data!E31,"N/D") -> N/D | F16: <0.5x very healthy · 0.5-1.5x normal · >1.5x leveraged. | G16: =IFERROR(IF(Input_Data!B29/Input_Data!B31<0.5,"🟢 GOOD",IF(Input_Data!B29/Input_Data!B31<1.5,"🟡 REVIEW","🔴 ALERT")),"⚪ N/A") -> ⚪ N/A
A17: Debt / EBITDA | B17: =IFERROR(Input_Data!B29/Input_Data!B16,"N/D") -> N/D | C17: =IFERROR(Input_Data!C29/Input_Data!C16,"N/D") -> N/D | D17: =IFERROR(Input_Data!D29/Input_Data!D16,"N/D") -> N/D | E17: =IFERROR(Input_Data!E29/Input_Data!E16,"N/D") -> N/D | F17: Years to repay debt from EBITDA. <2x excellent · 2-4x normal · >5x alert. | G17: =IFERROR(IF(Input_Data!B29/Input_Data!B16<2,"🟢 GOOD",IF(Input_Data!B29/Input_Data!B16<4,"🟡 REVIEW","🔴 ALERT")),"⚪ N/A") -> ⚪ N/A
A18: Interest Coverage (EBIT / Interest) | B18: =IFERROR(Input_Data!B17/Input_Data!B18,"N/D") -> N/D | C18: =IFERROR(Input_Data!C17/Input_Data!C18,"N/D") -> N/D | D18: =IFERROR(Input_Data!D17/Input_Data!D18,"N/D") -> N/D | E18: =IFERROR(Input_Data!E17/Input_Data!E18,"N/D") -> N/D | F18: >3x comfortable · 1.5-3x tight · <1.5x dangerous. | G18: =IFERROR(IF(Input_Data!B17/Input_Data!B18>3,"🟢 GOOD",IF(Input_Data!B17/Input_Data!B18>=1.5,"🟡 REVIEW","🔴 ALERT")),"⚪ N/A") -> ⚪ N/A
A19: ── DIVIDENDS & CASH (Does it generate and share cash?) ──
A20: Dividend Yield | B20: =IFERROR(Input_Data!B23/Input_Data!B9,"N/D") -> N/D | C20: =IFERROR(Input_Data!C23/Input_Data!C9,"N/D") -> N/D | D20: =IFERROR(Input_Data!D23/Input_Data!D9,"N/D") -> N/D | E20: =IFERROR(Input_Data!E23/Input_Data!E9,"N/D") -> N/D | F20: Annual return via dividend. 2-5% attractive. >7% may signal risk. | G20: =IFERROR(IF(Input_Data!B9=0,"⚪ N/A",IF(Input_Data!B23/Input_Data!B9>0.02,"🟢 GOOD",IF(Input_Data!B23/Input_Data!B9>0,"🟡 REVIEW","⚪ NO DIV"))),"⚪ N/A") -> ⚪ N/A
A21: FCF Yield (Free Cash / Market Cap) | B21: =IFERROR(Input_Data!B36/(Input_Data!B9*Input_Data!B10),"N/D") -> N/D | C21: =IFERROR(Input_Data!C36/(Input_Data!C9*Input_Data!C10),"N/D") -> N/D | D21: =IFERROR(Input_Data!D36/(Input_Data!D9*Input_Data!D10),"N/D") -> N/D | E21: =IFERROR(Input_Data!E36/(Input_Data!E9*Input_Data!E10),"N/D") -> N/D | F21: Free cash as % of market cap. >5% very attractive · 2-5% normal · <2% alert. | G21: =IFERROR(IF(Input_Data!B9=0,"⚪ N/A",IF(Input_Data!B36/(Input_Data!B9*Input_Data!B10)>0.05,"🟢 GOOD",IF(Input_Data!B36/(Input_Data!B9*Input_Data!B10)>0.02,"🟡 REVIEW","🔴 ALERT"))),"⚪ N/A") -> ⚪ N/A
A23: ⚠️ Signals are general guides. Always benchmark vs the sector. A P/E of 30x can be fair in tech but expensive in consumer staples.

Sheet My_Position
A1: 📊 MY POSITION IN [TICKER] — Personal Analysis
A2: 🟡 YELLOW = update manually · 🔵 BLUE = auto-calculated · Source: stockanalysis.com/msft
A3: 🛒 MY PURCHASES IN MSFT
A4: FIELD | B4: VALUE | C4: NOTE
A5: Avg Purchase Price (USD) → From your GBM transaction history | C5: Your weighted average cost across all purchases
A6: Number of Shares → From your GBM account | C6: Total shares in your portfolio
A7: Total Investment Cost (USD) (auto-calculated) | B7: =B5*B6 -> 0 | C7: Your total investment in this asset
A8: 💹 CURRENT PRICE (update each time you analyse)
A9: Current Price per Share (USD) → stockanalysis.com/msft → live price | C9: Update this price each time you analyse MSFT
A10: Current Position Value (USD) (auto-calculated) | B10: =B9*B6 -> 0 | C10: Current market value of your shares
A11: 📈 GAIN / LOSS
A12: Total Gain / Loss (USD) | B12: =B10-B7 -> 0 | C12: Positive = unrealised gain · Negative = unrealised loss
A13: Return (%) | B13: =IFERROR(B10/B7-1,"N/D") -> N/D | C13: Your return on initial investment
A14: Gain / Loss per Share (USD) | B14: =IFERROR((B10-B7)/B6,"N/D") -> N/D | C14: How much you gain or lose per share
A15: Have I recouped my investment? | B15: =IF(B9>B5,"✅ YES — current price > purchase price","❌ NO — current price < purchase price") -> ❌ NO — current price < purchase price | C15: Compares current price vs your average purchase price
A16: Dividendo anual recibido (USD) (con 3 acciones) | B16: =B6*3.64 -> 0 | C16: Annual dividend of $3.64 per share × your 3 shares
A17: 🔬 ANALYST OPINION (additional context — not a guarantee)
A18: Analyst Recommendation → stockanalysis.com → 'Analysts' tab | C18: Institutional analyst consensus. Not a guarantee — context only.
A19: Analyst Price Target (USD) → stockanalysis.com → 'Price Target' | C19: Implied upside potential: 15.0% from current price. Update each quarter.
A20: ⏱️ RULE OF 72 — Growth projections
A21: SCENARIO | B21: ANNUAL RATE | C21: YEARS TO DOUBLE | D21: VALUE IN 5 YEARS (USD) | E21: VALUE IN 10 YEARS (USD)
A22: Actual return on your purchase to date | B22: =IFERROR((B9-B5)/B5,"N/D") -> N/D | C22: =IFERROR(72/(B22*100),"N/D") -> N/D | D22: =IFERROR(B10*(1+B22)^5,"N/D") -> N/D | E22: =IFERROR(B10*(1+B22)^10,"N/D") -> N/D
A23: Reference: S&P 500 average annual return (10 years) → This 15% is the historical return of the INDEX, not the P/E → Use it to compare how much your money could grow if it were in VOO | B23: 0.15 | C23: =IFERROR(72/(B23*100),"N/D") -> 4.8 | D23: =IFERROR(B10*(1+B23)^5,"N/D") -> 0 | E23: =IFERROR(B10*(1+B23)^10,"N/D") -> 0
A24: Base scenario (10%/yr) | B24: 0.1 | C24: =IFERROR(72/(B24*100),"N/D") -> 7.2 | D24: =IFERROR(B10*(1+B24)^5,"N/D") -> 0 | E24: =IFERROR(B10*(1+B24)^10,"N/D") -> 0
A25: Conservative scenario (7%/yr) | B25: 0.07 | C25: =IFERROR(72/(B25*100),"N/D") -> 10.285714 | D25: =IFERROR(B10*(1+B25)^5,"N/D") -> 0 | E25: =IFERROR(B10*(1+B25)^10,"N/D") -> 0
A27: 🎯 BUY ZONE — When is it attractive to buy more MSFT?
A28: 🟡 Update yellow cells each month or quarter · stockanalysis.com/msft has everything on one screen
A29: DATA FIELD / EXACT SOURCE | B29: CURRENT VALUE (🟡 you fill this in) | C29: ATTRACTIVE ZONE | D29: EXPENSIVE ZONE | E29: SIGNAL
A30: ── 1. P/E RATIO — Is the stock expensive? ──
A31: P/E (TTM) → stockanalysis.com/msft → 'PE Ratio (TTM)' | C31: < 22.0x (annual low) | D31: > 38.0x (annual high) | E31: =IF(B31<22,"🟢 ATTRACTIVE",IF(B31>38,"🔴 EXPENSIVE","🟡 NORMAL")) -> 🟢 ATTRACTIVE
A32: Forward P/E (next 12 months) → stockanalysis.com → 'Forward PE' | C32: Forward P/E uses estimated future earnings — more relevant than TTM for growth companies. Lower Forward P/E = market expects earnings to grow.
A33: Historical Avg P/E → stockanalysis.com/stocks/msft/financials/ → 'PE Ratio' column → average last 5 fiscal years manually | C33: Average the 'PE Ratio' column for the last 5 fiscal years at stockanalysis.com/stocks/msft/financials/
A34: 📊 P/E vs. Historical Average (premium or discount vs own history) | B34: =IFERROR(B31/B33-1,"N/A") -> N/A | C34: =IFERROR(IF(B31<B33*0.9,"Trading "&TEXT(ABS(1-B31/B33)*100,"0.0")&"% cheaper than its historical average",IF(B31>B33*1.1,"Trading "&TEXT(ABS(1-B31/B33)*100,"0.0")&"% more expensive than its historical average","Trading near its historical P/E average")),"N/A") -> Trading near its historical P/E average | E34: =IFERROR(IF(B31<B33*0.9,"🟢 ATTRACTIVE",IF(B31>B33*1.1,"🔴 EXPENSIVE","🟡 NORMAL")),"⚪ N/A") -> 🟡 NORMAL
A35: P/B (Price / Book) → stockanalysis.com → Statistics → 'P/B Ratio' | C35: < 1.5x (cheap vs book value) | D35: > 5.0x (expensive — normal in tech) | E35: =IF(B35<1.5,"🟢 ATTRACTIVE",IF(B35>5,"🔴 EXPENSIVE","🟡 NORMAL")) -> 🟢 ATTRACTIVE
A36: ── 2. PRICE IN ANNUAL RANGE ──
A37: 52-Week Low (USD) → stockanalysis.com/msft → '52-Week Range' | C37: Buying near this price = attractive zone | E37: 🟢 Low zone
A38: 52-Week High (USD) → stockanalysis.com/msft → '52-Week Range' | C38: Avoid buying near this price | E38: 🔴 High zone
A39: % Position in annual range (0% = low · 100% = high) | B39: =IFERROR((B9-B37)/(B38-B37),"N/A") -> N/A | C39: < 33% → lower third (attractive) | D39: > 67% → upper third (expensive) | E39: =IFERROR(IF(B39<0.33,"🟢 ATTRACTIVE",IF(B39<0.67,"🟡 NORMAL","🔴 EXPENSIVE")),"⚪ N/A") -> 🔴 EXPENSIVE
A40: ── 3. TARGET PRICE ──
A41: Target Entry Price (USD) Formula: current price × (historical P/E ÷ current P/E) = price if P/E reverted to its 5yr average | B41: =IFERROR(B9*(B33/B31),"N/A") -> N/A | C41: ⚠️ This price is NOT VALID until you fill in the historical P/E above. Once filled, the target price calculates automatically. | E41: =IFERROR(IF(B9<B41,"🟢 BUY ZONE",IF(B9<B41*1.05,"🟡 CLOSE","🔴 WAIT")),"⚪ N/D") -> 🟢 BUY ZONE
...

Sheet DuPont_Pyramid
A1: 🔬 DuPont Ratio Pyramid — [Company Name] ([TICKER])
A2: ROE = Net Margin × Asset Turnover × Financial Leverage · All values from Input_Data · Q1 = most recent
A3: Each box shows 4 quarters: Q1 (latest) | Q2 | Q3 | Q4 (oldest)
G4: ROE — Return on Equity
G5: =IFERROR(Input_Data!B21/Input_Data!B31,"N/A") -> N/A | I5: =IFERROR(Input_Data!C21/Input_Data!C31,"N/A") -> N/A | J5: =IFERROR(Input_Data!D21/Input_Data!D31,"N/A") -> N/A | K5: =IFERROR(Input_Data!E21/Input_Data!E31,"N/A") -> N/A
A7: NET MARGIN = Net Income ÷ Revenue | G7: ASSET TURNOVER = Revenue ÷ Total Assets | M7: FINANCIAL LEVERAGE = Assets ÷ Equity
A8: =IFERROR(Input_Data!B21/Input_Data!B12,"N/A") -> N/A | C8: =IFERROR(Input_Data!C21/Input_Data!C12,"N/A") -> N/A | D8: =IFERROR(Input_Data!D21/Input_Data!D12,"N/A") -> N/A | F8: =IFERROR(Input_Data!E21/Input_Data!E12,"N/A") -> N/A | G8: =IFERROR(Input_Data!B12/Input_Data!B27,"N/A") -> N/A | I8: =IFERROR(Input_Data!C12/Input_Data!C27,"N/A") -> N/A | J8: =IFERROR(Input_Data!D12/Input_Data!D27,"N/A") -> N/A | L8: =IFERROR(Input_Data!E12/Input_Data!E27,"N/A") -> N/A | M8: =IFERROR(Input_Data!B27/Input_Data!B31,"N/A") -> N/A | O8: =IFERROR(Input_Data!C27/Input_Data!C31,"N/A") -> N/A | P8: =IFERROR(Input_Data!D27/Input_Data!D31,"N/A") -> N/A | R8: =IFERROR(Input_Data!E27/Input_Data!E31,"N/A") -> N/A
A10: GROSS MARGIN | D10: OPERATING MARGIN | G10: CURRENT ASSETS / REV | J10: INVENTORY TURNOVER | M10: DEBT / EQUITY | P10: CURRENT RATIO
A11: =IFERROR(Input_Data!B14/Input_Data!B12,"N/A") -> N/A | B11: =IFERROR(Input_Data!C14/Input_Data!C12,"N/A") -> N/A | C11: =IFERROR(Input_Data!D14/Input_Data!D12,"N/A") -> N/A | D11: =IFERROR(Input_Data!B17/Input_Data!B12,"N/A") -> N/A | E11: =IFERROR(Input_Data!C17/Input_Data!C12,"N/A") -> N/A | F11: =IFERROR(Input_Data!D17/Input_Data!D12,"N/A") -> N/A | G11: =IFERROR(Input_Data!B26/Input_Data!B12,"N/A") -> N/A | H11: =IFERROR(Input_Data!C26/Input_Data!C12,"N/A") -> N/A | I11: =IFERROR(Input_Data!D26/Input_Data!D12,"N/A") -> N/A | J11: =IFERROR(Input_Data!B12/Input_Data!B27,"N/A") -> N/A | K11: =IFERROR(Input_Data!C12/Input_Data!C27,"N/A") -> N/A | L11: =IFERROR(Input_Data!D12/Input_Data!D27,"N/A") -> N/A | M11: =IFERROR(Input_Data!B29/Input_Data!B31,"N/A") -> N/A | N11: =IFERROR(Input_Data!C29/Input_Data!C31,"N/A") -> N/A | O11: =IFERROR(Input_Data!D29/Input_Data!D31,"N/A") -> N/A | P11: =IFERROR(Input_Data!B26/Input_Data!B28,"N/A") -> N/A | Q11: =IFERROR(Input_Data!C26/Input_Data!C28,"N/A") -> N/A | R11: =IFERROR(Input_Data!D26/Input_Data!D28,"N/A") -> N/A
A13: REVENUE | C13: COGS | D13: EBIT | F13: INTEREST | G13: TOTAL ASSETS | J13: NET INCOME | M13: TOTAL LIABILITIES | P13: COMMON EQUITY
A14: =IFERROR(Input_Data!B12/1000000000,"N/A") -> 0 | B14: =IFERROR(Input_Data!C12/1000000000,"N/A") -> 0 | C14: =IFERROR(Input_Data!B13/1000000000,"N/A") -> 0 | D14: =IFERROR(Input_Data!B17/1000000000,"N/A") -> 0 | E14: =IFERROR(Input_Data!C17/1000000000,"N/A") -> 0 | F14: =IFERROR(Input_Data!B18/1000000000,"N/A") -> 0 | G14: =IFERROR(Input_Data!B27/1000000000,"N/A") -> 0 | H14: =IFERROR(Input_Data!C27/1000000000,"N/A") -> 0 | I14: =IFERROR(Input_Data!D27/1000000000,"N/A") -> 0 | J14: =IFERROR(Input_Data!B21/1000000000,"N/A") -> 0 | K14: =IFERROR(Input_Data!C21/1000000000,"N/A") -> 0 | L14: =IFERROR(Input_Data!D21/1000000000,"N/A") -> 0 | M14: =IFERROR(Input_Data!B30/1000000000,"N/A") -> 0 | N14: =IFERROR(Input_Data!C30/1000000000,"N/A") -> 0 | O14: =IFERROR(Input_Data!D30/1000000000,"N/A") -> 0 | P14: =IFERROR(Input_Data!B31/1000000000,"N/A") -> 0 | Q14: =IFERROR(Input_Data!C31/1000000000,"N/A") -> 0 | R14: =IFERROR(Input_Data!D31/1000000000,"N/A") -> 0
A15: USD values = billions (B) · Net Margin × Asset Turnover × Financial Leverage = ROE · Refresh Power Query to update
A16: WHAT DRIVES MSFT'S ROE?
A17: High Net Margin (~40%) | E17: Microsoft's cloud and software licensing model generates very high margins with low incremental cost per unit sold. This is the PRIMARY driver of its ROE.
A18: Low Asset Turnover (~0.12x) | E18: MSFT has a massive asset base (cloud infrastructure, data centres, Activision goodwill). It generates less revenue per dollar of assets than pure-software peers — a natural trade-off for infrastructure scale.
A19: Moderate Leverage (~1.7x) | E19: MSFT is conservatively financed for its size. Leverage is NOT the key driver — improving margins (Azure growth, Copilot monetisation) or asset efficiency would lift ROE without added risk.

Sheet Sector_Benchmark
A1: 🔍 SECTOR BENCHMARK
A2: Enter data from the most recent quarter for each company. Sources: Yahoo Finance, Macrotrends, FMP.
A3: RATIO / METRIC | B3: Company 1 (main) | C3: Company 2 | D3: Company 3 | E3: Sector Average | F3: WINNER?
A4: Ticker / Name | F4: —
A5: ── VALUATION ──
A6: P/E — Price/Earnings (x) | F6: =IFERROR(_xlfn.IFS(B6=MIN(B6:D6),"🏆 Company 1",C6=MIN(B6:D6),"🏆 Company 2",D6=MIN(B6:D6),"🏆 Company 3"),"—") -> 🏆 Company 1
A7: P/B — Price/Book Value (x) | F7: =IFERROR(_xlfn.IFS(B7=MIN(B7:D7),"🏆 Company 1",C7=MIN(B7:D7),"🏆 Company 2",D7=MIN(B7:D7),"🏆 Company 3"),"—") -> 🏆 Company 1
A8: ── PROFITABILITY ──
A9: Gross Margin (%) | F9: =IFERROR(_xlfn.IFS(B9=MAX(B9:D9),"🏆 Company 1",C9=MAX(B9:D9),"🏆 Company 2",D9=MAX(B9:D9),"🏆 Company 3"),"—") -> 🏆 Company 1
A10: Operating Margin (%) | F10: =IFERROR(_xlfn.IFS(B10=MAX(B10:D10),"🏆 Company 1",C10=MAX(B10:D10),"🏆 Company 2",D10=MAX(B10:D10),"🏆 Company 3"),"—") -> 🏆 Company 1
A11: Net Margin (%) | F11: =IFERROR(_xlfn.IFS(B11=MAX(B11:D11),"🏆 Company 1",C11=MAX(B11:D11),"🏆 Company 2",D11=MAX(B11:D11),"🏆 Company 3"),"—") -> 🏆 Company 1
A12: ROE — Return on Equity (%) | F12: =IFERROR(_xlfn.IFS(B12=MAX(B12:D12),"🏆 Company 1",C12=MAX(B12:D12),"🏆 Company 2",D12=MAX(B12:D12),"🏆 Company 3"),"—") -> 🏆 Company 1
A13: ── DEBT ──
A14: Current Ratio (x) | F14: =IFERROR(_xlfn.IFS(B14=MAX(B14:D14),"🏆 Company 1",C14=MAX(B14:D14),"🏆 Company 2",D14=MAX(B14:D14),"🏆 Company 3"),"—") -> 🏆 Company 1
A15: Debt/EBITDA (x) | F15: =IFERROR(_xlfn.IFS(B15=MIN(B15:D15),"🏆 Company 1",C15=MIN(B15:D15),"🏆 Company 2",D15=MIN(B15:D15),"🏆 Company 3"),"—") -> 🏆 Company 1
A16: Debt/Equity (x) | F16: =IFERROR(_xlfn.IFS(B16=MIN(B16:D16),"🏆 Company 1",C16=MIN(B16:D16),"🏆 Company 2",D16=MIN(B16:D16),"🏆 Company 3"),"—") -> 🏆 Company 1
A17: ── DIVIDENDS & CASH ──
A18: Dividend Yield (%) | F18: =IFERROR(_xlfn.IFS(B18=MAX(B18:D18),"🏆 Company 1",C18=MAX(B18:D18),"🏆 Company 2",D18=MAX(B18:D18),"🏆 Company 3"),"—") -> 🏆 Company 1
A19: FCF Yield (%) | F19: =IFERROR(_xlfn.IFS(B19=MAX(B19:D19),"🏆 Company 1",C19=MAX(B19:D19),"🏆 Company 2",D19=MAX(B19:D19),"🏆 Company 3"),"—") -> 🏆 Company 1
A20: ── GROWTH ──
A21: Revenue Growth YoY (%) | F21: =IFERROR(_xlfn.IFS(B21=MAX(B21:D21),"🏆 Company 1",C21=MAX(B21:D21),"🏆 Company 2",D21=MAX(B21:D21),"🏆 Company 3"),"—") -> 🏆 Company 1
A22: Net Income Growth YoY (%) | F22: =IFERROR(_xlfn.IFS(B22=MAX(B22:D22),"🏆 Company 1",C22=MAX(B22:D22),"🏆 Company 2",D22=MAX(B22:D22),"🏆 Company 3"),"—") -> 🏆 Company 1
A24: 🟡 YELLOW cells = enter the most recent Q data for each company · Sources: Yahoo Finance, Macrotrends.net, FMP

Sheet Guide
A1: 📖 USER GUIDE — AF_Acciones Template
A2: STEP | B2: WHAT TO DO
A3: 1. Set up FMP | B3: Go to Setup sheet → paste your API Key in B5 → enter the US ticker in B6.
A4: 2. Refresh Power Query | B4: Data → Queries & Connections → right-click each query → Refresh. Data populates FMP_Data automatically.
A5: 3. For MX stocks | B5: Fill Input_Data manually from Yahoo Finance (ticker.MX) or BMV. Yellow cells = manual entry.
A6: 4. Read Analysis | B6: 🟢 GOOD · 🟡 REVIEW · 🔴 ALERT. Traffic light based on Q1 — most recent quarter.
A7: 5. Benchmark | B7: Fill Sector_Benchmark with the same ratios for 2 competitors in the sector.
A8: 6. Save | B8: Use naming convention: AF_Acciones_TICKER_YYYYMM.xlsx E.g.: AF_Stocks_ADBE_202608.xlsx
A10: US SOURCES | B10: financialmodelingprep.com (FMP) · SEC EDGAR (edgar.sec.gov) · stockanalysis.com · Yahoo Finance
A11: MX SOURCES | B11: Yahoo Finance · stockanalysis.com · With your broker
A12: KEY RATIOS
A13: P/E Ratio | B13: Years to recoup from earnings. <15x cheap · >25x expensive.
A14: P/B Ratio | B14: Price vs book value. <1x technically cheap.
A15: Operating Margin | B15: Core profitability. >15% good for most sectors.
A16: ROE | B16: >15% excellent. How well it uses shareholders' capital.
A17: Debt/EBITDA | B17: <2x excellent. >5x over-leverage alert.
A18: FCF Yield | B18: >5% very attractive. Free cash as % of price.
A19: Dividend Yield | B19: 2-5% attractive. >7% may signal a cut risk.
