Workbook

Sheet income-statement_symbol=MSFT&pe
A1: Column1.date | B1: Column1.symbol | C1: Column1.reportedCurrency | D1: Column1.cik | E1: Column1.filingDate | F1: Column1.acceptedDate | G1: Column1.fiscalYear | H1: Column1.period | I1: Column1.revenue | J1: Column1.costOfRevenue | K1: Column1.grossProfit | L1: Column1.researchAndDevelopmentExpenses | M1: Column1.generalAndAdministrativeExpenses | N1: Column1.sellingAndMarketingExpenses | O1: Column1.sellingGeneralAndAdministrativeExpenses | P1: Column1.otherExpenses | Q1: Column1.operatingExpenses | R1: Column1.costAndExpenses | S1: Column1.netInterestIncome | T1: Column1.interestIncome | U1: Column1.interestExpense | V1: Column1.depreciationAndAmortization | W1: Column1.ebitda | X1: Column1.ebit | Y1: Column1.nonOperatingIncomeExcludingInterest | Z1: Column1.operatingIncome | AA1: Column1.totalOtherIncomeExpensesNet | AB1: Column1.incomeBeforeTax | AC1: Column1.incomeTaxExpense | AD1: Column1.netIncomeFromContinuingOperations | AE1: Column1.netIncomeFromDiscontinuedOperations | AF1: Column1.otherAdjustmentsToNetIncome | AG1: Column1.netIncome | AH1: Column1.netIncomeDeductions | AI1: Column1.bottomLineNetIncome | AJ1: Column1.eps | AK1: Column1.epsDiluted | AL1: Column1.weightedAverageShsOut | AM1: Column1.weightedAverageShsOutDil
A2: 2026-06-30 | B2: MSFT | C2: USD | D2: 0000789019 | E2: 2026-07-29 | F2: 2026-07-29 16:08:01 | G2: 2026 | H2: Q4 | I2: 90007000000 | J2: 29525000000 | K2: 60482000000 | L2: 9997000000 | M2: 2287000000 | N2: 7595000000 | O2: 9882000000 | P2: 0 | Q2: 19879000000 | R2: 49404000000 | S2: -84000000 | T2: 755000000 | U2: 839000000 | V2: 6108000000 | W2: 50994000000 | X2: 44886000000 | Y2: -4283000000 | Z2: 40603000000 | AA2: 3444000000 | AB2: 44047000000 | AC2: 8281000000 | AD2: 35766000000 | AE2: 0 | AF2: 0 | AG2: 35766000000 | AH2: 0 | AI2: 35766000000 | AJ2: 4.81 | AK2: 4.8 | AL2: 7429000000 | AM2: 7453000000
A3: 2026-03-31 | B3: MSFT | C3: USD | D3: 0000789019 | E3: 2026-04-29 | F3: 2026-04-29 16:06:24 | G3: 2026 | H3: Q3 | I3: 82886000000 | J3: 26828000000 | K3: 56058000000 | L3: 8915000000 | M3: 1931000000 | N3: 6814000000 | O3: 8745000000 | P3: 0 | Q3: 17660000000 | R3: 44488000000 | S3: -48000000 | T3: 730000000 | U3: 778000000 | V3: 10167000000 | W3: 50285000000 | X3: 40118000000 | Y3: -1720000000 | Z3: 38398000000 | AA3: 942000000 | AB3: 39340000000 | AC3: 7562000000 | AD3: 31778000000 | AE3: 0 | AF3: 0 | AG3: 31778000000 | AH3: 0 | AI3: 31778000000 | AJ3: 4.28 | AK3: 4.27 | AL3: 7426000000 | AM3: 7445000000
A4: 2025-12-31 | B4: MSFT | C4: USD | D4: 0000789019 | E4: 2026-01-28 | F4: 2026-01-28 16:07:34 | G4: 2026 | H4: Q2 | I4: 81273000000 | J4: 25978000000 | K4: 55295000000 | L4: 8504000000 | M4: 1932000000 | N4: 6584000000 | O4: 8516000000 | P4: 0 | Q4: 17020000000 | R4: 42998000000 | S4: 104000000 | T4: 840000000 | U4: 736000000 | V4: 9198000000 | W4: 58180000000 | X4: 48982000000 | Y4: -10707000000 | Z4: 38275000000 | AA4: 9971000000 | AB4: 48246000000 | AC4: 9788000000 | AD4: 38458000000 | AE4: 0 | AF4: 0 | AG4: 38458000000 | AH4: 0 | AI4: 38458000000 | AJ4: 5.18 | AK4: 5.16 | AL4: 7431000000 | AM4: 7460000000
A5: 2025-09-30 | B5: MSFT | C5: USD | D5: 0000789019 | E5: 2025-10-29 | F5: 2025-10-29 16:10:48 | G5: 2026 | H5: Q1 | I5: 77673000000 | J5: 24043000000 | K5: 53630000000 | L5: 8146000000 | M5: 1806000000 | N5: 5717000000 | O5: 7523000000 | P5: 0 | Q5: 15669000000 | R5: 39712000000 | S5: 278000000 | T5: 976000000 | U5: 698000000 | V5: 13061000000 | W5: 48060000000 | X5: 34999000000 | Y5: 2962000000 | Z5: 37961000000 | AA5: -3660000000 | AB5: 34301000000 | AC5: 6554000000 | AD5: 27747000000 | AE5: 0 | AF5: 0 | AG5: 27747000000 | AH5: 0 | AI5: 27747000000 | AJ5: 3.73 | AK5: 3.72 | AL5: 7433000000 | AM5: 7466000000

Sheet balance-sheet-statement_symbol=
A1: Column1.date | B1: Column1.symbol | C1: Column1.reportedCurrency | D1: Column1.cik | E1: Column1.filingDate | F1: Column1.acceptedDate | G1: Column1.fiscalYear | H1: Column1.period | I1: Column1.cashAndCashEquivalents | J1: Column1.shortTermInvestments | K1: Column1.cashAndShortTermInvestments | L1: Column1.netReceivables | M1: Column1.accountsReceivables | N1: Column1.otherReceivables | O1: Column1.inventory | P1: Column1.prepaids | Q1: Column1.otherCurrentAssets | R1: Column1.totalCurrentAssets | S1: Column1.propertyPlantEquipmentNet | T1: Column1.goodwill | U1: Column1.intangibleAssets | V1: Column1.goodwillAndIntangibleAssets | W1: Column1.longTermInvestments | X1: Column1.taxAssets | Y1: Column1.otherNonCurrentAssets | Z1: Column1.totalNonCurrentAssets | AA1: Column1.otherAssets | AB1: Column1.totalAssets | AC1: Column1.totalPayables | AD1: Column1.accountPayables | AE1: Column1.otherPayables | AF1: Column1.accruedExpenses | AG1: Column1.shortTermDebt | AH1: Column1.capitalLeaseObligationsCurrent | AI1: Column1.taxPayables | AJ1: Column1.deferredRevenue | AK1: Column1.otherCurrentLiabilities | AL1: Column1.totalCurrentLiabilities | AM1: Column1.longTermDebt | AN1: Column1.capitalLeaseObligationsNonCurrent | AO1: Column1.deferredRevenueNonCurrent | AP1: Column1.deferredTaxLiabilitiesNonCurrent | AQ1: Column1.otherNonCurrentLiabilities | AR1: Column1.totalNonCurrentLiabilities | AS1: Column1.otherLiabilities | AT1: Column1.capitalLeaseObligations | AU1: Column1.totalLiabilities | AV1: Column1.treasuryStock | AW1: Column1.preferredStock | AX1: Column1.commonStock | AY1: Column1.retainedEarnings | AZ1: Column1.additionalPaidInCapital | BA1: Column1.accumulatedOtherComprehensiveIncomeLoss | BB1: Column1.otherTotalStockholdersEquity | BC1: Column1.totalStockholdersEquity | BD1: Column1.totalEquity | BE1: Column1.minorityInterest | BF1: Column1.totalLiabilitiesAndTotalEquity | BG1: Column1.totalInvestments | BH1: Column1.totalDebt | BI1: Column1.netDebt
A2: 2026-06-30 | B2: MSFT | C2: USD | D2: 0000789019 | E2: 2026-07-29 | F2: 2026-07-29 16:08:01 | G2: 2026 | H2: Q4 | I2: 20935000000 | J2: 55908000000 | K2: 76843000000 | L2: 80876000000 | M2: 80876000000 | N2: 0 | O2: 1397000000 | P2: 0 | Q2: 48594000000 | R2: 207710000000 | S2: 337253000000 | T2: 119651000000 | U2: 18609000000 | V2: 138260000000 | W2: 36348000000 | X2: 0 | Y2: 38805000000 | Z2: 550666000000 | AA2: 0 | AB2: 758376000000 | AC2: 44950000000 | AD2: 42416000000 | AE2: 2534000000 | AF2: 14945000000 | AG2: 9227000000 | AH2: 9678300000 | AI2: 0 | AJ2: 72965000000 | AK2: 17059700000 | AL2: 168825000000 | AM2: 31067000000 | AN2: 78836000000 | AO2: 2747000000 | AP2: 3054000000 | AQ2: 31460000000 | AR2: 147164000000 | AS2: 0 | AT2: 88514300000 | AU2: 315989000000 | AV2: 0 | AW2: 0 | AX2: 117406000000 | AY2: 328265000000 | AZ2: 0 | BA2: -3284000000 | BB2: 0 | BC2: 442387000000 | BD2: 442387000000 | BE2: 0 | BF2: 758376000000 | BG2: 92256000000 | BH2: 128808300000 | BI2: 107873300000
A3: 2026-03-31 | B3: MSFT | C3: USD | D3: 0000789019 | E3: 2026-04-29 | F3: 2026-04-29 16:06:24 | G3: 2026 | H3: Q3 | I3: 32105000000 | J3: 46167000000 | K3: 78272000000 | L3: 60041000000 | M3: 60041000000 | N3: 0 | O3: 1219000000 | P3: 0 | Q3: 35797000000 | R3: 175329000000 | S3: 307631000000 | T3: 119661000000 | U3: 19325000000 | V3: 138986000000 | W3: 33683000000 | X3: 0 | Y3: 38599000000 | Z3: 518899000000 | AA3: 0 | AB3: 694228000000 | AC3: 41076000000 | AD3: 37513000000 | AE3: 3563000000 | AF3: 0 | AG3: 8839000000 | AH3: 9598000000 | AI3: 3563000000 | AJ3: 50924000000 | AK3: 26224000000 | AL3: 136661000000 | AM3: 31423000000 | AN3: 75572000000 | AO3: 2753000000 | AP3: 2899000000 | AQ3: 30553000000 | AR3: 143200000000 | AS3: 0 | AT3: 85170000000 | AU3: 279861000000 | AV3: 0 | AW3: 0 | AX3: 115069000000 | AY3: 302526000000 | AZ3: 0 | BA3: -3228000000 | BB3: 0 | BC3: 414367000000 | BD3: 414367000000 | BE3: 0 | BF3: 694228000000 | BG3: 79850000000 | BH3: 125432000000 | BI3: 93327000000
A4: 2025-12-31 | B4: MSFT | C4: USD | D4: 0000789019 | E4: 2026-01-28 | F4: 2026-01-28 16:07:34 | G4: 2026 | H4: Q2 | I4: 24296000000 | J4: 65160000000 | K4: 89456000000 | L4: 56535000000 | M4: 56535000000 | N4: 0 | O4: 1059000000 | P4: 0 | Q4: 33140000000 | R4: 180190000000 | S4: 286229000000 | T4: 119622000000 | U4: 20289000000 | V4: 139911000000 | W4: 21202000000 | X4: 0 | Y4: 37770000000 | Z4: 485112000000 | AA4: 0 | AB4: 665302000000 | AC4: 39378000000 | AD4: 37328000000 | AE4: 2050000000 | AF4: 0 | AG4: 4837000000 | AH4: 9258000000 | AI4: 2050000000 | AJ4: 51376000000 | AK4: 25156000000 | AL4: 130005000000 | AM4: 35425000000 | AN4: 73758000000 | AO4: 2668000000 | AP4: 2876000000 | AQ4: 29695000000 | AR4: 144422000000 | AS4: 0 | AT4: 83016000000 | AU4: 274427000000 | AV4: 0 | AW4: 0 | AX4: 112788000000 | AY4: 280789000000 | AZ4: 0 | BA4: -2702000000 | BB4: 0 | BC4: 390875000000 | BD4: 390875000000 | BE4: 0 | BF4: 665302000000 | BG4: 86368000000 | BH4: 123278000000 | BI4: 98982000000
A5: 2025-09-30 | B5: MSFT | C5: USD | D5: 0000789019 | E5: 2025-10-29 | F5: 2025-10-29 16:10:48 | G5: 2026 | H5: Q1 | I5: 28849000000 | J5: 73156000000 | K5: 102005000000 | L5: 52894000000 | M5: 52894000000 | N5: 0 | O5: 1130000000 | P5: 0 | Q5: 33037000000 | R5: 189066000000 | S5: 255652000000 | T5: 119497000000 | U5: 21236000000 | V5: 140733000000 | W5: 10283000000 | X5: 0 | Y5: 40617000000 | Z5: 447285000000 | AA5: 0 | AB5: 636351000000 | AC5: 36235000000 | AD5: 32580000000 | AE5: 3655000000 | AF5: 0 | AG5: 7832000000 | AH5: 8820000000 | AI5: 3655000000 | AJ5: 58987000000 | AK5: 23122000000 | AL5: 134996000000 | AM5: 35376000000 | AN5: 68347000000 | AO5: 2546000000 | AP5: 2852000000 | AQ5: 29158000000 | AR5: 138279000000 | AS5: 0 | AT5: 77167000000 | AU5: 273275000000 | AV5: 0 | AW5: 0 | AX5: 110964000000 | AY5: 254873000000 | AZ5: 0 | BA5: -2761000000 | BB5: 0 | BC5: 363076000000 | BD5: 363076000000 | BE5: 0 | BF5: 636351000000 | BG5: 83439000000 | BH5: 120375000000 | BI5: 91526000000

Sheet cash-flow-statement_symbol=MSFT
A1: Column1.date | B1: Column1.symbol | C1: Column1.reportedCurrency | D1: Column1.cik | E1: Column1.filingDate | F1: Column1.acceptedDate | G1: Column1.fiscalYear | H1: Column1.period | I1: Column1.netIncome | J1: Column1.depreciationAndAmortization | K1: Column1.deferredIncomeTax | L1: Column1.stockBasedCompensation | M1: Column1.changeInWorkingCapital | N1: Column1.accountsReceivables | O1: Column1.inventory | P1: Column1.accountsPayables | Q1: Column1.otherWorkingCapital | R1: Column1.otherNonCashItems | S1: Column1.netCashProvidedByOperatingActivities | T1: Column1.investmentsInPropertyPlantAndEquipment | U1: Column1.acquisitionsNet | V1: Column1.purchasesOfInvestments | W1: Column1.salesMaturitiesOfInvestments | X1: Column1.otherInvestingActivities | Y1: Column1.netCashProvidedByInvestingActivities | Z1: Column1.netDebtIssuance | AA1: Column1.longTermNetDebtIssuance | AB1: Column1.shortTermNetDebtIssuance | AC1: Column1.netStockIssuance | AD1: Column1.netCommonStockIssuance | AE1: Column1.commonStockIssuance | AF1: Column1.commonStockRepurchased | AG1: Column1.netPreferredStockIssuance | AH1: Column1.netDividendsPaid | AI1: Column1.commonDividendsPaid | AJ1: Column1.preferredDividendsPaid | AK1: Column1.otherFinancingActivities | AL1: Column1.netCashProvidedByFinancingActivities | AM1: Column1.effectOfForexChangesOnCash | AN1: Column1.netChangeInCash | AO1: Column1.cashAtEndOfPeriod | AP1: Column1.cashAtBeginningOfPeriod | AQ1: Column1.operatingCashFlow | AR1: Column1.capitalExpenditure | AS1: Column1.freeCashFlow | AT1: Column1.incomeTaxesPaid | AU1: Column1.interestPaid
A2: 2026-06-30 | B2: MSFT | C2: USD | D2: 0000789019 | E2: 2026-07-29 | F2: 2026-07-29 16:08:01 | G2: 2026 | H2: Q4 | I2: 35766000000 | J2: 11022000000 | K2: 4650000000 | L2: 3122000000 | M2: 4624000000 | N2: -21084000000 | O2: -178000000 | P2: 2365000000 | Q2: 23521000000 | R2: -3743000000 | S2: 55441000000 | T2: -35802000000 | U2: -452000000 | V2: -18829000000 | W2: 10668000000 | X2: -10416000000 | Y2: -54831000000 | Z2: 0 | AA2: 0 | AB2: 0 | AC2: -4059000000 | AD2: -4059000000 | AE2: 520000000 | AF2: -4579000000 | AG2: 0 | AH2: -6758000000 | AI2: -6758000000 | AJ2: 0 | AK2: -962000000 | AL2: -11779000000 | AM2: -1000000 | AN2: -11170000000 | AO2: 20935000000 | AP2: 32105000000 | AQ2: 55441000000 | AR2: -35802000000 | AS2: 19639000000 | AT2: 0 | AU2: 0
A3: 2026-03-31 | B3: MSFT | C3: USD | D3: 0000789019 | E3: 2026-04-29 | F3: 2026-04-29 16:06:24 | G3: 2026 | H3: Q3 | I3: 31778000000 | J3: 10167000000 | K3: 2602000000 | L3: 3081000000 | M3: 331000000 | N3: -4707000000 | O3: -161000000 | P3: 2320000000 | Q3: 2879000000 | R3: -1280000000 | S3: 46679000000 | T3: -30876000000 | U3: -258000000 | V3: -12006000000 | W3: 18334000000 | X3: -2599000000 | Y3: -27405000000 | Z3: 0 | AA3: 0 | AB3: 0 | AC3: -4086000000 | AD3: -4086000000 | AE3: 541000000 | AF3: -4627000000 | AG3: 0 | AH3: -6756000000 | AI3: -6756000000 | AJ3: 0 | AK3: -509000000 | AL3: -11351000000 | AM3: -114000000 | AN3: 7809000000 | AO3: 32105000000 | AP3: 24296000000 | AQ3: 46679000000 | AR3: -30876000000 | AS3: 15803000000 | AT3: 0 | AU3: 0
A4: 2025-12-31 | B4: MSFT | C4: USD | D4: 0000789019 | E4: 2026-01-28 | F4: 2026-01-28 16:07:34 | G4: 2026 | H4: Q2 | I4: 38458000000 | J4: 9198000000 | K4: 4446000000 | L4: 3219000000 | M4: -9632000000 | N4: -3436000000 | O4: 70000000 | P4: 1197000000 | Q4: -7463000000 | R4: -9931000000 | S4: 35758000000 | T4: -29876000000 | U4: -455000000 | V4: -9845000000 | W4: 18108000000 | X4: -637000000 | Y4: -22705000000 | Z4: -3000000000 | AA4: -3000000000 | AB4: 0 | AC4: -7156000000 | AD4: -7156000000 | AE4: 259000000 | AF4: -7415000000 | AG4: 0 | AH4: -6762000000 | AI4: -6762000000 | AJ4: 0 | AK4: -699000000 | AL4: -17617000000 | AM4: 11000000 | AN4: -4553000000 | AO4: 24296000000 | AP4: 28849000000 | AQ4: 35758000000 | AR4: -29876000000 | AS4: 5882000000 | AT4: 0 | AU4: 0
A5: 2025-09-30 | B5: MSFT | C5: USD | D5: 0000789019 | E5: 2025-10-29 | F5: 2025-10-29 16:10:48 | G5: 2026 | H5: Q1 | I5: 27747000000 | J5: 13061000000 | K5: 2491000000 | L5: 2983000000 | M5: -218000000 | N5: 16490000000 | O5: -192000000 | P5: -614000000 | Q5: -15902000000 | R5: -1007000000 | S5: 45057000000 | T5: -19394000000 | U5: -578000000 | V5: -17671000000 | W5: 9293000000 | X5: -6209000000 | Y5: -34559000000 | Z5: 0 | AA5: 0 | AB5: 0 | AC5: -4961000000 | AD5: -4961000000 | AE5: 689000000 | AF5: -5650000000 | AG5: 0 | AH5: -6169000000 | AI5: -6169000000 | AJ5: 0 | AK5: -669000000 | AL5: -11799000000 | AM5: -92000000 | AN5: -1393000000 | AO5: 28849000000 | AP5: 30242000000 | AQ5: 45057000000 | AR5: -19394000000 | AS5: 25663000000 | AT5: 0 | AU5: 0

Sheet Setup
A1: ⚙️ SETUP — AF_Acciones Template (US Stocks)
A2: Fill the GREEN cells before using. Power Query reads this sheet automatically.
A4: 🔑 FINANCIAL MODELING PREP (FMP) — US Stocks
A5: FMP API Key | C5: ⚠️ Paste your key from financialmodelingprep.com/dashboard
A6: Ticker (US company) | B6: MSFT | C6: E.g.: MSFT · ADBE · AMZN (letters only)
A7: Number of quarters | B7: 4 | C7: Max 5 on the free FMP plan
A9: FOREIGN STOCKS — Manual entry
A10: For foreign tickers there is no free API. Fill Input_Data manually from Yahoo Finance (e.g: ticker.MX)
A12: 📋 HOW TO USE POWER QUERY (US stocks)
A13: 1. Paste your API Key in the green cell B5 of this sheet.
A14: 2. Enter the US ticker in the green cell B6 (e.g.: ADBE).
A15: 3. Go to Data → Queries & Connections → right-click each query → Refresh.
A16: 4. Data will populate automatically in the FMP_Data sheet.
A17: 5. The Input_Data sheet pulls values from FMP_Data via formulas.
A18: 6. Go to Analysis to read the traffic-light signals.
A19: 7. Save the file as: AF_Stocks_TICKER_YYYYMM.xlsx

Sheet FMP_Data
A1: 📡 FMP DATA — Populated automatically by Power Query
A2: DO NOT edit this sheet manually. Use Data → Refresh All to update.
A4: ⚡ POWER QUERY: Data → Get Data → From Web → paste the URL below with your API key. Repeat for Income Statement, Balance Sheet and Cash Flow.
A6: Income Statement (4 quarters): | B6: https://financialmodelingprep.com/stable/income-statement?symbol=TICKER&period=quarter&limit=4&apikey=YOUR_KEY
A7: Balance Sheet (4 quarters): | B7: https://financialmodelingprep.com/stable/balance-sheet-statement?symbol=TICKER&period=quarter&limit=4&apikey=YOUR_KEY
A8: Cash Flow (4 quarters): | B8: https://financialmodelingprep.com/stable/cash-flow-statement?symbol=TICKER&period=quarter&limit=4&apikey=YOUR_KEY
A9: Current Price: | B9: https://financialmodelingprep.com/stable/quote?symbol=TICKER&apikey=YOUR_KEY
A11: Replace TICKER with the symbol (e.g.: ADBE) and YOUR_KEY with your FMP API key. After setting up Power Query, this sheet fills automatically.
A13: Field | B13: Q1 (most recent) | C13: Q2 | D13: Q3 | E13: Q4 | F13: FMP Source
A14: date (quarter end date)
A15: revenue (Total Revenue)
A16: costOfRevenue (Cost of Revenue)
A17: grossProfit (Gross Profit)
A18: operatingExpenses (Operating Expense)
A19: ebitda (EBITDA)
A20: operatingIncome (EBIT / Operating Income)
A21: interestExpense (Interest Expense)
A22: incomeBeforeTax (Pretax Income / EBT)
A23: incomeTaxExpense (Tax Provision)
A24: netIncome (Net Income)
A25: eps (Diluted EPS)
... A37: weightedAverageShsOutDil (Shares Outstanding) [IS]

Sheet Input_Data
A1: 📊 FINANCIAL ANALYSIS — INPUT DATA (Stocks)
A2: 🟡 YELLOW = fill manually · 🔵 BLUE = auto-populated from FMP_Data · Sources: FMP · Yahoo Finance · stockanalysis.com
A3: FIELD | B3: Q1 (most recent) | C3: Q2 | D3: Q3 | E3: Q4 (oldest)
A4: 📅 Quarter end date | B4: =TEXT('[1]income-statement_symbol=MSFT&pe'!A2,"DD/MM/YYYY") -> 30/06/2026 | C4: =TEXT('[1]income-statement_symbol=MSFT&pe'!A3,"DD/MM/YYYY") -> 31/03/2026 | D4: =TEXT('[1]income-statement_symbol=MSFT&pe'!A4,"DD/MM/YYYY") -> 31/12/2025 | E4: =TEXT('[1]income-statement_symbol=MSFT&pe'!A5,"DD/MM/YYYY") -> 30/09/2025
A5: GENERAL INFORMATION
A6: Company Name | B6: Microsoft Corporation
A7: Ticker / Symbol | B7: MSFT
A8: Market (US / MX / other) | B8: US
A9: Share Price (USD or MXN) → Update manually each quarter · stockanalysis.com | B9: 481.15 | C9: 369.46 | D9: 483.64 | E9: 519.68
A10: Shares Outstanding | B10: 7426000000 | C10: 7426000000 | D10: 7426000000 | E10: 7426000000
A11: 📋 INCOME STATEMENT
A12: Total Revenue / Net Sales | B12: =IFERROR('[1]income-statement_symbol=MSFT&pe'!I2,"N/D") -> 90007000000 | C12: =IFERROR('[1]income-statement_symbol=MSFT&pe'!I3,"N/D") -> 82886000000 | D12: =IFERROR('[1]income-statement_symbol=MSFT&pe'!I4,"N/D") -> 81273000000 | E12: =IFERROR('[1]income-statement_symbol=MSFT&pe'!I5,"N/D") -> 77673000000
A13: Cost of Revenue (COGS) | B13: =IFERROR('[1]income-statement_symbol=MSFT&pe'!J2,"N/D") -> 29525000000 | C13: =IFERROR('[1]income-statement_symbol=MSFT&pe'!J3,"N/D") -> 26828000000 | D13: =IFERROR('[1]income-statement_symbol=MSFT&pe'!J4,"N/D") -> 25978000000 | E13: =IFERROR('[1]income-statement_symbol=MSFT&pe'!J5,"N/D") -> 24043000000
A14: Gross Profit | B14: =IFERROR('[1]income-statement_symbol=MSFT&pe'!K2,"N/D") -> 60482000000 | C14: =IFERROR('[1]income-statement_symbol=MSFT&pe'!K3,"N/D") -> 56058000000 | D14: =IFERROR('[1]income-statement_symbol=MSFT&pe'!K4,"N/D") -> 55295000000 | E14: =IFERROR('[1]income-statement_symbol=MSFT&pe'!K5,"N/D") -> 53630000000
A15: Operating Expense (SG&A + R&D) | B15: =IFERROR('[1]income-statement_symbol=MSFT&pe'!Q2,"N/D") -> 19879000000 | C15: =IFERROR('[1]income-statement_symbol=MSFT&pe'!Q3,"N/D") -> 17660000000 | D15: =IFERROR('[1]income-statement_symbol=MSFT&pe'!Q4,"N/D") -> 17020000000 | E15: =IFERROR('[1]income-statement_symbol=MSFT&pe'!Q5,"N/D") -> 15669000000
A16: EBITDA | B16: =IFERROR('[1]income-statement_symbol=MSFT&pe'!W2,"N/D") -> 50994000000 | C16: =IFERROR('[1]income-statement_symbol=MSFT&pe'!W3,"N/D") -> 50285000000 | D16: =IFERROR('[1]income-statement_symbol=MSFT&pe'!W4,"N/D") -> 58180000000 | E16: =IFERROR('[1]income-statement_symbol=MSFT&pe'!W5,"N/D") -> 48060000000
A17: EBIT / Operating Income | B17: =IFERROR('[1]income-statement_symbol=MSFT&pe'!X2,"N/D") -> 44886000000 | C17: =IFERROR('[1]income-statement_symbol=MSFT&pe'!X3,"N/D") -> 40118000000 | D17: =IFERROR('[1]income-statement_symbol=MSFT&pe'!X4,"N/D") -> 48982000000 | E17: =IFERROR('[1]income-statement_symbol=MSFT&pe'!X5,"N/D") -> 34999000000
A18: Interest Expense | B18: =IFERROR('[1]income-statement_symbol=MSFT&pe'!U2,"N/D") -> 839000000 | C18: =IFERROR('[1]income-statement_symbol=MSFT&pe'!U3,"N/D") -> 778000000 | D18: =IFERROR('[1]income-statement_symbol=MSFT&pe'!U4,"N/D") -> 736000000 | E18: =IFERROR('[1]income-statement_symbol=MSFT&pe'!U5,"N/D") -> 698000000
A19: Pretax Income (EBT) | B19: =IFERROR('[1]income-statement_symbol=MSFT&pe'!AB2,"N/D") -> 44047000000 | C19: =IFERROR('[1]income-statement_symbol=MSFT&pe'!AB3,"N/D") -> 39340000000 | D19: =IFERROR('[1]income-statement_symbol=MSFT&pe'!AB4,"N/D") -> 48246000000 | E19: =IFERROR('[1]income-statement_symbol=MSFT&pe'!AB5,"N/D") -> 34301000000
A20: Tax Provision | B20: =IFERROR('[1]income-statement_symbol=MSFT&pe'!AC2,"N/D") -> 8281000000 | C20: =IFERROR('[1]income-statement_symbol=MSFT&pe'!AC3,"N/D") -> 7562000000 | D20: =IFERROR('[1]income-statement_symbol=MSFT&pe'!AC4,"N/D") -> 9788000000 | E20: =IFERROR('[1]income-statement_symbol=MSFT&pe'!AC5,"N/D") -> 6554000000
A21: Net Income | B21: =IFERROR('[1]income-statement_symbol=MSFT&pe'!AG2,"N/D") -> 35766000000 | C21: =IFERROR('[1]income-statement_symbol=MSFT&pe'!AG3,"N/D") -> 31778000000 | D21: =IFERROR('[1]income-statement_symbol=MSFT&pe'!AG4,"N/D") -> 38458000000 | E21: =IFERROR('[1]income-statement_symbol=MSFT&pe'!AG5,"N/D") -> 27747000000
A22: Diluted EPS | B22: =IFERROR('[1]income-statement_symbol=MSFT&pe'!AK2,"N/D") -> 4.8 | C22: =IFERROR('[1]income-statement_symbol=MSFT&pe'!AK3,"N/D") -> 4.27 | D22: =IFERROR('[1]income-statement_symbol=MSFT&pe'!AK4,"N/D") -> 5.16 | E22: =IFERROR('[1]income-statement_symbol=MSFT&pe'!AK5,"N/D") -> 3.72
A23: Dividend Per Share → Yahoo Finance → Statistics | B23: 0.91 | C23: 0.91 | D23: 0.91 | E23: 0.91
A24: 🏦 BALANCE SHEET
A25: Cash & Cash Equivalents | B25: =IFERROR('[1]balance-sheet-statement_symbol='!I2,"N/D") -> 20935000000 | C25: =IFERROR('[1]balance-sheet-statement_symbol='!I3,"N/D") -> 32105000000 | D25: =IFERROR('[1]balance-sheet-statement_symbol='!I4,"N/D") -> 24296000000 | E25: =IFERROR('[1]balance-sheet-statement_symbol='!I5,"N/D") -> 28849000000
A26: Total Current Assets | B26: =IFERROR('[1]balance-sheet-statement_symbol='!R2,"N/D") -> 207710000000 | C26: =IFERROR('[1]balance-sheet-statement_symbol='!R3,"N/D") -> 175329000000 | D26: =IFERROR('[1]balance-sheet-statement_symbol='!R4,"N/D") -> 180190000000 | E26: =IFERROR('[1]balance-sheet-statement_symbol='!R5,"N/D") -> 189066000000
A27: Total Assets | B27: =IFERROR('[1]balance-sheet-statement_symbol='!AB2,"N/D") -> 758376000000 | C27: =IFERROR('[1]balance-sheet-statement_symbol='!AB3,"N/D") -> 694228000000 | D27: =IFERROR('[1]balance-sheet-statement_symbol='!AB4,"N/D") -> 665302000000 | E27: =IFERROR('[1]balance-sheet-statement_symbol='!AB5,"N/D") -> 636351000000
A28: Total Current Liabilities | B28: =IFERROR('[1]balance-sheet-statement_symbol='!AL2,"N/D") -> 168825000000 | C28: =IFERROR('[1]balance-sheet-statement_symbol='!AL3,"N/D") -> 136661000000 | D28: =IFERROR('[1]balance-sheet-statement_symbol='!AL4,"N/D") -> 130005000000 | E28: =IFERROR('[1]balance-sheet-statement_symbol='!AL5,"N/D") -> 134996000000
A29: Total Debt (ST + LT) | B29: =IFERROR('[1]balance-sheet-statement_symbol='!BH2,"N/D") -> 128808300000 | C29: =IFERROR('[1]balance-sheet-statement_symbol='!BH3,"N/D") -> 125432000000 | D29: =IFERROR('[1]balance-sheet-statement_symbol='!BH4,"N/D") -> 123278000000 | E29: =IFERROR('[1]balance-sheet-statement_symbol='!BH5,"N/D") -> 120375000000
A30: Total Liabilities | B30: =IFERROR('[1]balance-sheet-statement_symbol='!AU2,"N/D") -> 315989000000 | C30: =IFERROR('[1]balance-sheet-statement_symbol='!AU3,"N/D") -> 279861000000 | D30: =IFERROR('[1]balance-sheet-statement_symbol='!AU4,"N/D") -> 274427000000 | E30: =IFERROR('[1]balance-sheet-statement_symbol='!AU5,"N/D") -> 273275000000
A31: Common Stock Equity | B31: =IFERROR('[1]balance-sheet-statement_symbol='!BC2,"N/D") -> 442387000000 | C31: =IFERROR('[1]balance-sheet-statement_symbol='!BC3,"N/D") -> 414367000000 | D31: =IFERROR('[1]balance-sheet-statement_symbol='!BC4,"N/D") -> 390875000000 | E31: =IFERROR('[1]balance-sheet-statement_symbol='!BC5,"N/D") -> 363076000000
A32: Book Value Per Share | B32: =IFERROR(B31/B10,"N/D") -> 59.572717 | C32: =IFERROR(C31/C10,"N/D") -> 55.799488 | D32: =IFERROR(D31/D10,"N/D") -> 52.636009 | E32: =IFERROR(E31/E10,"N/D") -> 48.89254
A33: 💵 CASH FLOW STATEMENT
A34: Operating Cash Flow (CFO) | B34: =IFERROR('[1]cash-flow-statement_symbol=MSFT'!S2,"N/D") -> 55441000000 | C34: =IFERROR('[1]cash-flow-statement_symbol=MSFT'!S3,"N/D") -> 46679000000 | D34: =IFERROR('[1]cash-flow-statement_symbol=MSFT'!S4,"N/D") -> 35758000000 | E34: =IFERROR('[1]cash-flow-statement_symbol=MSFT'!S5,"N/D") -> 45057000000
A35: Capital Expenditure (CAPEX) | B35: =IFERROR('[1]cash-flow-statement_symbol=MSFT'!AR2,"N/D") -> -35802000000 | C35: =IFERROR('[1]cash-flow-statement_symbol=MSFT'!AR3,"N/D") -> -30876000000 | D35: =IFERROR('[1]cash-flow-statement_symbol=MSFT'!AR4,"N/D") -> -29876000000 | E35: =IFERROR('[1]cash-flow-statement_symbol=MSFT'!AR5,"N/D") -> -19394000000
A36: Free Cash Flow (FCF = CFO − CAPEX) | B36: =IFERROR('[1]cash-flow-statement_symbol=MSFT'!AS2,"N/D") -> 19639000000 | C36: =IFERROR('[1]cash-flow-statement_symbol=MSFT'!AS3,"N/D") -> 15803000000 | D36: =IFERROR('[1]cash-flow-statement_symbol=MSFT'!AS4,"N/D") -> 5882000000 | E36: =IFERROR('[1]cash-flow-statement_symbol=MSFT'!AS5,"N/D") -> 25663000000
A37: Dividends Paid | B37: =IFERROR('[1]cash-flow-statement_symbol=MSFT'!AI2,"N/D") -> -6758000000 | C37: =IFERROR('[1]cash-flow-statement_symbol=MSFT'!AI3,"N/D") -> -6756000000 | D37: =IFERROR('[1]cash-flow-statement_symbol=MSFT'!AI4,"N/D") -> -6762000000 | E37: =IFERROR('[1]cash-flow-statement_symbol=MSFT'!AI5,"N/D") -> -6169000000
A38: Share Buybacks | B38: =IFERROR('[1]cash-flow-statement_symbol=MSFT'!AF2,"N/D") -> -4579000000 | C38: =IFERROR('[1]cash-flow-statement_symbol=MSFT'!AF3,"N/D") -> -4627000000 | D38: =IFERROR('[1]cash-flow-statement_symbol=MSFT'!AF4,"N/D") -> -7415000000 | E38: =IFERROR('[1]cash-flow-statement_symbol=MSFT'!AF5,"N/D") -> -5650000000
A40: 🔵 BLUE = auto-populated from Power Query (FMP) / or manually · 🟡 YELLOW = fill manually · Share Price always manual · Dividend Per Share manual from Yahoo Finance → Statistics
A41: 📌 File naming: AF_Stocks_TICKER_YYYYMM.xlsx E.g.: AF_Stocks_ADBE_202608.xlsx

Sheet Analysis
A1: 📈 FINANCIAL RATIO ANALYSIS
A2: Ratios calculate automatically from Input_Data. Refresh Power Query to update.
A3: 🟢 GOOD = Healthy 🟡 REVIEW = Caution 🔴 ALERT = Risk ⚪ N/A = No data (Traffic light based on Q1 — most recent quarter)
A4: RATIO | B4: Q1 (latest) | C4: Q2 | D4: Q3 | E4: Q4 (oldest) | F4: INTERPRETATION | G4: SIGNAL
A5: 📅 Reference date | B5: =TEXT('[1]income-statement_symbol=MSFT&pe'!A2,"DD/MM/YYYY") -> 30/06/2026 | C5: =TEXT('[1]income-statement_symbol=MSFT&pe'!A3,"DD/MM/YYYY") -> 31/03/2026 | D5: =TEXT('[1]income-statement_symbol=MSFT&pe'!A4,"DD/MM/YYYY") -> 31/12/2025 | E5: =TEXT('[1]income-statement_symbol=MSFT&pe'!A5,"DD/MM/YYYY") -> 30/09/2025
A6: ── VALUATION (Is the stock expensive?) ──
A7: P/E — Price / Earnings | B7: =IFERROR(Input_Data!B9/(Input_Data!B22*4),"N/A") -> 25.059896 | C7: =IFERROR(Input_Data!C9/(Input_Data!C22*4),"N/A") -> 21.631148 | D7: =IFERROR(Input_Data!D9/(Input_Data!D22*4),"N/A") -> 23.432171 | E7: =IFERROR(Input_Data!E9/(Input_Data!E22*4),"N/A") -> 34.924731 | F7: Years to recoup from earnings. <15x cheap · 15-25x fair · >25x expensive. | G7: =IFERROR(IF(Input_Data!B9=0,"⚪ N/A",IF(Input_Data!B9/(Input_Data!B22*4)<15,"🟢 GOOD",IF(Input_Data!B9/(Input_Data!B22*4)<25,"🟡 REVIEW","🔴 ALERT"))),"⚪ N/A") -> 🔴 ALERT
A8: P/B — Price / Book Value | B8: =IFERROR(Input_Data!B9/Input_Data!B32,"N/D") -> 8.0766838 | C8: =IFERROR(Input_Data!C9/Input_Data!C32,"N/D") -> 6.6212077 | D8: =IFERROR(Input_Data!D9/Input_Data!D32,"N/D") -> 9.1883867 | E8: =IFERROR(Input_Data!E9/Input_Data!E32,"N/D") -> 10.629024 | F8: <1x cheap · 1-3x normal · >3x expensive or intangibles-heavy. | G8: =IFERROR(IF(Input_Data!B9=0,"⚪ N/A",IF(Input_Data!B9/Input_Data!B32<1.5,"🟢 GOOD",IF(Input_Data!B9/Input_Data!B32<3,"🟡 REVIEW","🔴 ALERT"))),"⚪ N/A") -> 🔴 ALERT
A9: ── PROFITABILITY (Does it make money?) ──
A10: Gross Margin | B10: =IFERROR(Input_Data!B14/Input_Data!B12,"N/D") -> 0.67196996 | C10: =IFERROR(Input_Data!C14/Input_Data!C12,"N/D") -> 0.67632652 | D10: =IFERROR(Input_Data!D14/Input_Data!D12,"N/D") -> 0.68036125 | E10: =IFERROR(Input_Data!E14/Input_Data!E12,"N/D") -> 0.69045872 | F10: Higher = more efficient. Tech >60% · Industrial >30% · Retail ~25%. | G10: =IFERROR(IF(Input_Data!B14/Input_Data!B12>0.4,"🟢 GOOD",IF(Input_Data!B14/Input_Data!B12>0.2,"🟡 REVIEW","🔴 ALERT")),"⚪ N/A") -> 🟢 GOOD
A11: Operating Margin (EBIT / Revenue) | B11: =IFERROR(Input_Data!B17/Input_Data!B12,"N/D") -> 0.49869455 | C11: =IFERROR(Input_Data!C17/Input_Data!C12,"N/D") -> 0.48401419 | D11: =IFERROR(Input_Data!D17/Input_Data!D12,"N/D") -> 0.60268478 | E11: =IFERROR(Input_Data!E17/Input_Data!E12,"N/D") -> 0.45059416 | F11: Core profitability. >15% good · 8-15% normal · <8% alert. | G11: =IFERROR(IF(Input_Data!B17/Input_Data!B12>0.15,"🟢 GOOD",IF(Input_Data!B17/Input_Data!B12>0.08,"🟡 REVIEW","🔴 ALERT")),"⚪ N/A") -> 🟢 GOOD
A12: Net Margin | B12: =IFERROR(Input_Data!B21/Input_Data!B12,"N/D") -> 0.39736909 | C12: =IFERROR(Input_Data!C21/Input_Data!C12,"N/D") -> 0.38339406 | D12: =IFERROR(Input_Data!D21/Input_Data!D12,"N/D") -> 0.47319528 | E12: =IFERROR(Input_Data!E21/Input_Data!E12,"N/D") -> 0.35722838 | F12: What remains per $100 of revenue. >10% good · 5-10% normal · <5% alert. | G12: =IFERROR(IF(Input_Data!B21/Input_Data!B12>0.1,"🟢 GOOD",IF(Input_Data!B21/Input_Data!B12>0.05,"🟡 REVIEW","🔴 ALERT")),"⚪ N/A") -> 🟢 GOOD
A13: ROE — Return on Equity | B13: =IFERROR(Input_Data!B21/Input_Data!B31,"N/D") -> 0.080847765 | C13: =IFERROR(Input_Data!C21/Input_Data!C31,"N/D") -> 0.07669047 | D13: =IFERROR(Input_Data!D21/Input_Data!D31,"N/D") -> 0.098389511 | E13: =IFERROR(Input_Data!E21/Input_Data!E31,"N/D") -> 0.076422016 | F13: Returns on shareholders' capital. >15% excellent · 10-15% good · <10% review. | G13: =IFERROR(IF(Input_Data!B21/Input_Data!B31>0.15,"🟢 GOOD",IF(Input_Data!B21/Input_Data!B31>0.1,"🟡 REVIEW","🔴 ALERT")),"⚪ N/A") -> 🔴 ALERT
A14: ── DEBT & SOLVENCY (Can it pay what it owes?) ──
A15: Current Ratio | B15: =IFERROR(Input_Data!B26/Input_Data!B28,"N/D") -> 1.2303273 | C15: =IFERROR(Input_Data!C26/Input_Data!C28,"N/D") -> 1.2829483 | D15: =IFERROR(Input_Data!D26/Input_Data!D28,"N/D") -> 1.3860236 | E15: =IFERROR(Input_Data!E26/Input_Data!E28,"N/D") -> 1.4005304 | F15: Short-term liquidity. >2x comfortable · 1-2x normal · <1x risk. | G15: =IFERROR(IF(Input_Data!B26/Input_Data!B28>2,"🟢 GOOD",IF(Input_Data!B26/Input_Data!B28>=1,"🟡 REVIEW","🔴 ALERT")),"⚪ N/A") -> 🟡 REVIEW
A16: Debt / Equity | B16: =IFERROR(Input_Data!B29/Input_Data!B31,"N/D") -> 0.29116656 | C16: =IFERROR(Input_Data!C29/Input_Data!C31,"N/D") -> 0.3027075 | D16: =IFERROR(Input_Data!D29/Input_Data!D31,"N/D") -> 0.31538983 | E16: =IFERROR(Input_Data!E29/Input_Data!E31,"N/D") -> 0.33154216 | F16: <0.5x very healthy · 0.5-1.5x normal · >1.5x leveraged. | G16: =IFERROR(IF(Input_Data!B29/Input_Data!B31<0.5,"🟢 GOOD",IF(Input_Data!B29/Input_Data!B31<1.5,"🟡 REVIEW","🔴 ALERT")),"⚪ N/A") -> 🟢 GOOD
A17: Debt / EBITDA | B17: =IFERROR(Input_Data!B29/Input_Data!B16,"N/D") -> 2.5259501 | C17: =IFERROR(Input_Data!C29/Input_Data!C16,"N/D") -> 2.4944218 | D17: =IFERROR(Input_Data!D29/Input_Data!D16,"N/D") -> 2.1189068 | E17: =IFERROR(Input_Data!E29/Input_Data!E16,"N/D") -> 2.5046816 | F17: Years to repay debt from EBITDA. <2x excellent · 2-4x normal · >5x alert. | G17: =IFERROR(IF(Input_Data!B29/Input_Data!B16<2,"🟢 GOOD",IF(Input_Data!B29/Input_Data!B16<4,"🟡 REVIEW","🔴 ALERT")),"⚪ N/A") -> 🟡 REVIEW
A18: Interest Coverage (EBIT / Interest) | B18: =IFERROR(Input_Data!B17/Input_Data!B18,"N/D") -> 53.499404 | C18: =IFERROR(Input_Data!C17/Input_Data!C18,"N/D") -> 51.565553 | D18: =IFERROR(Input_Data!D17/Input_Data!D18,"N/D") -> 66.55163 | E18: =IFERROR(Input_Data!E17/Input_Data!E18,"N/D") -> 50.141834 | F18: >3x comfortable · 1.5-3x tight · <1.5x dangerous. | G18: =IFERROR(IF(Input_Data!B17/Input_Data!B18>3,"🟢 GOOD",IF(Input_Data!B17/Input_Data!B18>=1.5,"🟡 REVIEW","🔴 ALERT")),"⚪ N/A") -> 🟢 GOOD
A19: ── DIVIDENDS & CASH (Does it generate and share cash?) ──
A20: Dividend Yield | B20: =IFERROR(Input_Data!B23/Input_Data!B9,"N/D") -> 0.0018913021 | C20: =IFERROR(Input_Data!C23/Input_Data!C9,"N/D") -> 0.0024630542 | D20: =IFERROR(Input_Data!D23/Input_Data!D9,"N/D") -> 0.0018815648 | E20: =IFERROR(Input_Data!E23/Input_Data!E9,"N/D") -> 0.0017510776 | F20: Annual return via dividend. 2-5% attractive. >7% may signal risk. | G20: =IFERROR(IF(Input_Data!B9=0,"⚪ N/A",IF(Input_Data!B23/Input_Data!B9>0.02,"🟢 GOOD",IF(Input_Data!B23/Input_Data!B9>0,"🟡 REVIEW","⚪ NO DIV"))),"⚪ N/A") -> 🟡 REVIEW
A21: FCF Yield (Free Cash / Market Cap) | B21: =IFERROR(Input_Data!B36/(Input_Data!B9*Input_Data!B10),"N/D") -> 0.0054964709 | C21: =IFERROR(Input_Data!C36/(Input_Data!C9*Input_Data!C10),"N/D") -> 0.0057599295 | D21: =IFERROR(Input_Data!D36/(Input_Data!D9*Input_Data!D10),"N/D") -> 0.001637751 | E21: =IFERROR(Input_Data!E36/(Input_Data!E9*Input_Data!E10),"N/D") -> 0.0066499208 | F21: Free cash as % of market cap. >5% very attractive · 2-5% normal · <2% alert. | G21: =IFERROR(IF(Input_Data!B9=0,"⚪ N/A",IF(Input_Data!B36/(Input_Data!B9*Input_Data!B10)>0.05,"🟢 GOOD",IF(Input_Data!B36/(Input_Data!B9*Input_Data!B10)>0.02,"🟡 REVIEW","🔴 ALERT"))),"⚪ N/A") -> 🔴 ALERT
A23: ⚠️ Signals are general guides. Always benchmark vs the sector. A P/E of 30x can be fair in tech but expensive in consumer staples.

Sheet My_Position
A1: 📊 MY POSITION IN MSFT — Personal Analysis
A2: 🟡 YELLOW = update manually · 🔵 BLUE = auto-calculated · Source: stockanalysis.com/msft
A3: 🛒 MY PURCHASES IN MSFT
A4: FIELD | B4: VALUE | C4: NOTE
A5: Avg Purchase Price (USD) → From your GBM transaction history | B5: 467.2 | C5: Your weighted average cost across all purchases
A6: Number of Shares → From your GBM account | B6: 3 | C6: Total shares in your portfolio
A7: Total Investment Cost (USD) (auto-calculated) | B7: =B5*B6 -> 1401.6 | C7: Your total investment in this asset
A8: 💹 CURRENT PRICE (update each time you analyse)
A9: Current Price per Share (USD) → stockanalysis.com/msft → live price | B9: 481.15 | C9: Update this price each time you analyse MSFT
A10: Current Position Value (USD) (auto-calculated) | B10: =B9*B6 -> 1443.45 | C10: Current market value of your shares
A11: 📈 GAIN / LOSS
A12: Total Gain / Loss (USD) | B12: =B10-B7 -> 41.85 | C12: Positive = unrealised gain · Negative = unrealised loss
A13: Return (%) | B13: =IFERROR(B10/B7-1,"N/D") -> 0.029858733 | C13: Your return on initial investment
A14: Gain / Loss per Share (USD) | B14: =IFERROR((B10-B7)/B6,"N/D") -> 13.95 | C14: How much you gain or lose per share
A15: Have I recouped my investment? | B15: =IF(B9>B5,"✅ YES — current price > purchase price","❌ NO — current price < purchase price") -> ✅ YES — current price > purchase price | C15: Compares current price vs your average purchase price
A16: Dividendo anual recibido (USD) (con 3 acciones) | B16: =B6*3.64 -> 10.92 | C16: Annual dividend of $3.64 per share × your 3 shares
A17: 🔬 ANALYST OPINION (additional context — not a guarantee)
A18: Analyst Recommendation → stockanalysis.com → 'Analysts' tab | B18: Strong Buy | C18: Institutional analyst consensus. Not a guarantee — context only.
A19: Analyst Price Target (USD) → stockanalysis.com → 'Price Target' | B19: 569.56 | C19: Implied upside potential: 15.0% from current price. Update each quarter.
A20: ⏱️ RULE OF 72 — Growth projections
A21: SCENARIO | B21: ANNUAL RATE | C21: YEARS TO DOUBLE | D21: VALUE IN 5 YEARS (USD) | E21: VALUE IN 10 YEARS (USD)
A22: Actual return on your purchase to date | B22: =IFERROR((B9-B5)/B5,"N/D") -> 0.029858733 | C22: =IFERROR(72/(B22*100),"N/D") -> 24.113548 | D22: =IFERROR(B10*(1+B22)^5,"N/D") -> 1672.207 | E22: =IFERROR(B10*(1+B22)^10,"N/D") -> 1937.2171
A23: Reference: S&P 500 average annual return (10 years) → This 15% is the historical return of the INDEX, not the P/E → Use it to compare how much your money could grow if it were in VOO | B23: 0.15 | C23: =IFERROR(72/(B23*100),"N/D") -> 4.8 | D23: =IFERROR(B10*(1+B23)^5,"N/D") -> 2903.2935 | E23: =IFERROR(B10*(1+B23)^10,"N/D") -> 5839.5603
A24: Base scenario (10%/yr) | B24: 0.1 | C24: =IFERROR(72/(B24*100),"N/D") -> 7.2 | D24: =IFERROR(B10*(1+B24)^5,"N/D") -> 2324.6907 | E24: =IFERROR(B10*(1+B24)^10,"N/D") -> 3743.9376
A25: Conservative scenario (7%/yr) | B25: 0.07 | C25: =IFERROR(72/(B25*100),"N/D") -> 10.285714 | D25: =IFERROR(B10*(1+B25)^5,"N/D") -> 2024.5133 | E25: =IFERROR(B10*(1+B25)^10,"N/D") -> 2839.4846
A27: 🎯 BUY ZONE — When is it attractive to buy more MSFT?
A28: 🟡 Update yellow cells each month or quarter · stockanalysis.com/msft has everything on one screen
A29: DATA FIELD / EXACT SOURCE | B29: CURRENT VALUE (🟡 you fill this in) | C29: ATTRACTIVE ZONE | D29: EXPENSIVE ZONE | E29: SIGNAL
A30: ── 1. P/E RATIO — Is the stock expensive? ──
A31: P/E (TTM) → stockanalysis.com/msft → 'PE Ratio (TTM)' | B31: 26.81 | C31: < 22.0x (annual low) | D31: > 38.0x (annual high) | E31: =IF(B31<22,"🟢 ATTRACTIVE",IF(B31>38,"🔴 EXPENSIVE","🟡 NORMAL")) -> 🟡 NORMAL
A32: Forward P/E (next 12 months) → stockanalysis.com → 'Forward PE' | B32: 25.13 | C32: Forward P/E uses estimated future earnings — more relevant than TTM for growth companies. Lower Forward P/E = market expects earnings to grow.
A33: Historical Avg P/E → stockanalysis.com/stocks/msft/financials/ → 'PE Ratio' column → average last 5 fiscal years manually | B33: 30.63545 | C33: Average the 'PE Ratio' column for the last 5 fiscal years at stockanalysis.com/stocks/msft/financials/
A34: 📊 P/E vs. Historical Average (premium or discount vs own history) | B34: =IFERROR(B31/B33-1,"N/A") -> -0.12487004 | C34: =IFERROR(IF(B31<B33*0.9,"Trading "&TEXT(ABS(1-B31/B33)*100,"0.0")&"% cheaper than its historical average",IF(B31>B33*1.1,"Trading "&TEXT(ABS(1-B31/B33)*100,"0.0")&"% more expensive than its historical average","Trading near its historical P/E average")),"N/A") -> Trading 12.5% cheaper than its historical average | E34: =IFERROR(IF(B31<B33*0.9,"🟢 ATTRACTIVE",IF(B31>B33*1.1,"🔴 EXPENSIVE","🟡 NORMAL")),"⚪ N/A") -> 🟢 ATTRACTIVE
A35: P/B (Price / Book) → stockanalysis.com → Statistics → 'P/B Ratio' | B35: 8.13 | C35: < 1.5x (cheap vs book value) | D35: > 5.0x (expensive — normal in tech) | E35: =IF(B35<1.5,"🟢 ATTRACTIVE",IF(B35>5,"🔴 EXPENSIVE","🟡 NORMAL")) -> 🔴 EXPENSIVE
A36: ── 2. PRICE IN ANNUAL RANGE ──
A37: 52-Week Low (USD) → stockanalysis.com/msft → '52-Week Range' | B37: 349.2 | C37: Buying near this price = attractive zone | E37: 🟢 Low zone
A38: 52-Week High (USD) → stockanalysis.com/msft → '52-Week Range' | B38: 553.72 | C38: Avoid buying near this price | E38: 🔴 High zone
A39: % Position in annual range (0% = low · 100% = high) | B39: =IFERROR((B9-B37)/(B38-B37),"N/A") -> 0.64516918 | C39: < 33% → lower third (attractive) | D39: > 67% → upper third (expensive) | E39: =IFERROR(IF(B39<0.33,"🟢 ATTRACTIVE",IF(B39<0.67,"🟡 NORMAL","🔴 EXPENSIVE")),"⚪ N/A") -> 🟡 NORMAL
A40: ── 3. TARGET PRICE ──
A41: Target Entry Price (USD) Formula: current price × (historical P/E ÷ current P/E) = price if P/E reverted to its 5yr average | B41: =IFERROR(B9*(B33/B31),"N/A") -> 549.80406 | C41: ⚠️ This price is NOT VALID until you fill in the historical P/E above. Once filled, the target price calculates automatically. | E41: =IFERROR(IF(B9<B41,"🟢 BUY ZONE",IF(B9<B41*1.05,"🟡 CLOSE","🔴 WAIT")),"⚪ N/D") -> 🟢 BUY ZONE
...

Sheet DuPont_Pyramid
A1: 🔬 DuPont Ratio Pyramid — Microsoft Corporation (MSFT)
A2: ROE = Net Margin × Asset Turnover × Financial Leverage · All values from Input_Data · Q1 = most recent
A3: Each box shows 4 quarters: Q1 (latest) | Q2 | Q3 | Q4 (oldest)
G4: ROE — Return on Equity
G5: =IFERROR(Input_Data!B21/Input_Data!B31,"N/A") -> 0.080847765 | I5: =IFERROR(Input_Data!C21/Input_Data!C31,"N/A") -> 0.07669047 | J5: =IFERROR(Input_Data!D21/Input_Data!D31,"N/A") -> 0.098389511 | K5: =IFERROR(Input_Data!E21/Input_Data!E31,"N/A") -> 0.076422016
A7: NET MARGIN = Net Income ÷ Revenue | G7: ASSET TURNOVER = Revenue ÷ Total Assets | M7: FINANCIAL LEVERAGE = Assets ÷ Equity
A8: =IFERROR(Input_Data!B21/Input_Data!B12,"N/A") -> 0.39736909 | C8: =IFERROR(Input_Data!C21/Input_Data!C12,"N/A") -> 0.38339406 | D8: =IFERROR(Input_Data!D21/Input_Data!D12,"N/A") -> 0.47319528 | F8: =IFERROR(Input_Data!E21/Input_Data!E12,"N/A") -> 0.35722838 | G8: =IFERROR(Input_Data!B12/Input_Data!B27,"N/A") -> 0.11868387 | I8: =IFERROR(Input_Data!C12/Input_Data!C27,"N/A") -> 0.11939305 | J8: =IFERROR(Input_Data!D12/Input_Data!D27,"N/A") -> 0.12215956 | L8: =IFERROR(Input_Data!E12/Input_Data!E27,"N/A") -> 0.12206 | M8: =IFERROR(Input_Data!B27/Input_Data!B31,"N/A") -> 1.7142818 | O8: =IFERROR(Input_Data!C27/Input_Data!C31,"N/A") -> 1.675394 | P8: =IFERROR(Input_Data!D27/Input_Data!D31,"N/A") -> 1.7020838 | R8: =IFERROR(Input_Data!E27/Input_Data!E31,"N/A") -> 1.7526661
A10: GROSS MARGIN | D10: OPERATING MARGIN | G10: CURRENT ASSETS / REV | J10: INVENTORY TURNOVER | M10: DEBT / EQUITY | P10: CURRENT RATIO
A11: =IFERROR(Input_Data!B14/Input_Data!B12,"N/A") -> 0.67196996 | B11: =IFERROR(Input_Data!C14/Input_Data!C12,"N/A") -> 0.67632652 | C11: =IFERROR(Input_Data!D14/Input_Data!D12,"N/A") -> 0.68036125 | D11: =IFERROR(Input_Data!B17/Input_Data!B12,"N/A") -> 0.49869455 | E11: =IFERROR(Input_Data!C17/Input_Data!C12,"N/A") -> 0.48401419 | F11: =IFERROR(Input_Data!D17/Input_Data!D12,"N/A") -> 0.60268478 | G11: =IFERROR(Input_Data!B26/Input_Data!B12,"N/A") -> 2.3077094 | H11: =IFERROR(Input_Data!C26/Input_Data!C12,"N/A") -> 2.1153029 | I11: =IFERROR(Input_Data!D26/Input_Data!D12,"N/A") -> 2.2170955 | J11: =IFERROR(Input_Data!B12/Input_Data!B27,"N/A") -> 0.11868387 | K11: =IFERROR(Input_Data!C12/Input_Data!C27,"N/A") -> 0.11939305 | L11: =IFERROR(Input_Data!D12/Input_Data!D27,"N/A") -> 0.12215956 | M11: =IFERROR(Input_Data!B29/Input_Data!B31,"N/A") -> 0.29116656 | N11: =IFERROR(Input_Data!C29/Input_Data!C31,"N/A") -> 0.3027075 | O11: =IFERROR(Input_Data!D29/Input_Data!D31,"N/A") -> 0.31538983 | P11: =IFERROR(Input_Data!B26/Input_Data!B28,"N/A") -> 1.2303273 | Q11: =IFERROR(Input_Data!C26/Input_Data!C28,"N/A") -> 1.2829483 | R11: =IFERROR(Input_Data!D26/Input_Data!D28,"N/A") -> 1.3860236
A13: REVENUE | C13: COGS | D13: EBIT | F13: INTEREST | G13: TOTAL ASSETS | J13: NET INCOME | M13: TOTAL LIABILITIES | P13: COMMON EQUITY
A14: =IFERROR(Input_Data!B12/1000000000,"N/A") -> 90.007 | B14: =IFERROR(Input_Data!C12/1000000000,"N/A") -> 82.886 | C14: =IFERROR(Input_Data!B13/1000000000,"N/A") -> 29.525 | D14: =IFERROR(Input_Data!B17/1000000000,"N/A") -> 44.886 | E14: =IFERROR(Input_Data!C17/1000000000,"N/A") -> 40.118 | F14: =IFERROR(Input_Data!B18/1000000000,"N/A") -> 0.839 | G14: =IFERROR(Input_Data!B27/1000000000,"N/A") -> 758.376 | H14: =IFERROR(Input_Data!C27/1000000000,"N/A") -> 694.228 | I14: =IFERROR(Input_Data!D27/1000000000,"N/A") -> 665.302 | J14: =IFERROR(Input_Data!B21/1000000000,"N/A") -> 35.766 | K14: =IFERROR(Input_Data!C21/1000000000,"N/A") -> 31.778 | L14: =IFERROR(Input_Data!D21/1000000000,"N/A") -> 38.458 | M14: =IFERROR(Input_Data!B30/1000000000,"N/A") -> 315.989 | N14: =IFERROR(Input_Data!C30/1000000000,"N/A") -> 279.861 | O14: =IFERROR(Input_Data!D30/1000000000,"N/A") -> 274.427 | P14: =IFERROR(Input_Data!B31/1000000000,"N/A") -> 442.387 | Q14: =IFERROR(Input_Data!C31/1000000000,"N/A") -> 414.367 | R14: =IFERROR(Input_Data!D31/1000000000,"N/A") -> 390.875
A15: USD values = billions (B) · Net Margin × Asset Turnover × Financial Leverage = ROE · Refresh Power Query to update
A16: WHAT DRIVES MSFT'S ROE?
A17: High Net Margin (~40%) | E17: Microsoft's cloud and software licensing model generates very high margins with low incremental cost per unit sold. This is the PRIMARY driver of its ROE.
A18: Low Asset Turnover (~0.12x) | E18: MSFT has a massive asset base (cloud infrastructure, data centres, Activision goodwill). It generates less revenue per dollar of assets than pure-software peers — a natural trade-off for infrastructure scale.
A19: Moderate Leverage (~1.7x) | E19: MSFT is conservatively financed for its size. Leverage is NOT the key driver — improving margins (Azure growth, Copilot monetisation) or asset efficiency would lift ROE without added risk.

Sheet Sector_Benchmark
A1: 🔍 SECTOR BENCHMARK
A2: Enter data from the most recent quarter for each company. Sources: Yahoo Finance, Macrotrends, FMP.
A3: RATIO / METRIC | B3: Company 1 (main) | C3: Company 2 | D3: Company 3 | E3: Sector Average | F3: WINNER?
A4: Ticker / Name | F4: —
A5: ── VALUATION ──
A6: P/E — Price/Earnings (x) | F6: =IFERROR(_xlfn.IFS(B6=MIN(B6:D6),"🏆 Company 1",C6=MIN(B6:D6),"🏆 Company 2",D6=MIN(B6:D6),"🏆 Company 3"),"—") -> 🏆 Company 1
A7: P/B — Price/Book Value (x) | F7: =IFERROR(_xlfn.IFS(B7=MIN(B7:D7),"🏆 Company 1",C7=MIN(B7:D7),"🏆 Company 2",D7=MIN(B7:D7),"🏆 Company 3"),"—") -> 🏆 Company 1
A8: ── PROFITABILITY ──
A9: Gross Margin (%) | F9: =IFERROR(_xlfn.IFS(B9=MAX(B9:D9),"🏆 Company 1",C9=MAX(B9:D9),"🏆 Company 2",D9=MAX(B9:D9),"🏆 Company 3"),"—") -> 🏆 Company 1
A10: Operating Margin (%) | F10: =IFERROR(_xlfn.IFS(B10=MAX(B10:D10),"🏆 Company 1",C10=MAX(B10:D10),"🏆 Company 2",D10=MAX(B10:D10),"🏆 Company 3"),"—") -> 🏆 Company 1
A11: Net Margin (%) | F11: =IFERROR(_xlfn.IFS(B11=MAX(B11:D11),"🏆 Company 1",C11=MAX(B11:D11),"🏆 Company 2",D11=MAX(B11:D11),"🏆 Company 3"),"—") -> 🏆 Company 1
A12: ROE — Return on Equity (%) | F12: =IFERROR(_xlfn.IFS(B12=MAX(B12:D12),"🏆 Company 1",C12=MAX(B12:D12),"🏆 Company 2",D12=MAX(B12:D12),"🏆 Company 3"),"—") -> 🏆 Company 1
A13: ── DEBT ──
A14: Current Ratio (x) | F14: =IFERROR(_xlfn.IFS(B14=MAX(B14:D14),"🏆 Company 1",C14=MAX(B14:D14),"🏆 Company 2",D14=MAX(B14:D14),"🏆 Company 3"),"—") -> 🏆 Company 1
A15: Debt/EBITDA (x) | F15: =IFERROR(_xlfn.IFS(B15=MIN(B15:D15),"🏆 Company 1",C15=MIN(B15:D15),"🏆 Company 2",D15=MIN(B15:D15),"🏆 Company 3"),"—") -> 🏆 Company 1
A16: Debt/Equity (x) | F16: =IFERROR(_xlfn.IFS(B16=MIN(B16:D16),"🏆 Company 1",C16=MIN(B16:D16),"🏆 Company 2",D16=MIN(B16:D16),"🏆 Company 3"),"—") -> 🏆 Company 1
A17: ── DIVIDENDS & CASH ──
A18: Dividend Yield (%) | F18: =IFERROR(_xlfn.IFS(B18=MAX(B18:D18),"🏆 Company 1",C18=MAX(B18:D18),"🏆 Company 2",D18=MAX(B18:D18),"🏆 Company 3"),"—") -> 🏆 Company 1
A19: FCF Yield (%) | F19: =IFERROR(_xlfn.IFS(B19=MAX(B19:D19),"🏆 Company 1",C19=MAX(B19:D19),"🏆 Company 2",D19=MAX(B19:D19),"🏆 Company 3"),"—") -> 🏆 Company 1
A20: ── GROWTH ──
A21: Revenue Growth YoY (%) | F21: =IFERROR(_xlfn.IFS(B21=MAX(B21:D21),"🏆 Company 1",C21=MAX(B21:D21),"🏆 Company 2",D21=MAX(B21:D21),"🏆 Company 3"),"—") -> 🏆 Company 1
A22: Net Income Growth YoY (%) | F22: =IFERROR(_xlfn.IFS(B22=MAX(B22:D22),"🏆 Company 1",C22=MAX(B22:D22),"🏆 Company 2",D22=MAX(B22:D22),"🏆 Company 3"),"—") -> 🏆 Company 1
A24: 🟡 YELLOW cells = enter the most recent Q data for each company · Sources: Yahoo Finance, Macrotrends.net, FMP

Sheet Guide
A1: 📖 USER GUIDE — AF_Acciones Template
A2: STEP | B2: WHAT TO DO
A3: 1. Set up FMP | B3: Go to Setup sheet → paste your API Key in B5 → enter the US ticker in B6.
A4: 2. Refresh Power Query | B4: Data → Queries & Connections → right-click each query → Refresh. Data populates FMP_Data automatically.
A5: 3. For MX stocks | B5: Fill Input_Data manually from Yahoo Finance (ticker.MX) or BMV. Yellow cells = manual entry.
A6: 4. Read Analysis | B6: 🟢 GOOD · 🟡 REVIEW · 🔴 ALERT. Traffic light based on Q1 — most recent quarter.
A7: 5. Benchmark | B7: Fill Sector_Benchmark with the same ratios for 2 competitors in the sector.
A8: 6. Save | B8: Use naming convention: AF_Acciones_TICKER_YYYYMM.xlsx E.g.: AF_Stocks_ADBE_202608.xlsx
A10: US SOURCES | B10: financialmodelingprep.com (FMP) · SEC EDGAR (edgar.sec.gov) · stockanalysis.com · Yahoo Finance
A11: MX SOURCES | B11: Yahoo Finance · stockanalysis.com · With your broker
A12: KEY RATIOS
A13: P/E Ratio | B13: Years to recoup from earnings. <15x cheap · >25x expensive.
A14: P/B Ratio | B14: Price vs book value. <1x technically cheap.
A15: Operating Margin | B15: Core profitability. >15% good for most sectors.
A16: ROE | B16: >15% excellent. How well it uses shareholders' capital.
A17: Debt/EBITDA | B17: <2x excellent. >5x over-leverage alert.
A18: FCF Yield | B18: >5% very attractive. Free cash as % of price.
A19: Dividend Yield | B19: 2-5% attractive. >7% may signal a cut risk.
