Workbook

Sheet Input_Data
A1: 📊 ETF ANALYSIS — INPUT DATA
A2: 🟡 YELLOW = enter manually · Sources: Yahoo Finance (Statistics) · Issuer site (Vanguard, iShares, SPDR) · ETF.com
A3: FIELD | B3: ETF | C3: REFERENCE / BENCHMARK
A4: GENERAL INFORMATION
A5: ETF Name → Full name of the fund
A6: Ticker / Symbol
A7: Index Tracked → Index the ETF replicates
A8: Issuer → Vanguard / iShares / SPDR / other
A9: Asset Class → Equity / Bond / Commodity / Mixed
A10: Geography / Sector → USA / Europe / Emerging / Sector
A11: Currency → USD / EUR / MXN
A12: Analysis Date
A13: 📋 COST & SIZE
A14: Expense Ratio (%) → ETF issuer site or ETF.com → "Expense Ratio"
A15: AUM — Assets Under Management (USD billions) → ETF.com or Yahoo Finance → "Net Assets"
... A33: 🏆 TOP 10 HOLDINGS → ETF issuer site or ETF.com → Holdings tab
A34: RANK | B34: COMPANY / ASSET | C34: % OF FUND
A35: #1
A36: #2
A37: #3
A38: #4
A39: #5
A40: #6
A41: #7
A42: #8
A43: #9
A44: #10
A46: 📌 Sources: Yahoo Finance → Statistics (Expense Ratio, Yield, Beta, AUM) · ETF.com (Tracking Difference) · Issuer site (distributions, 30-Day SEC Yield)
A47: 📌 File naming: AF_ETF_TICKER_YYYYMM.xlsx e.g.: AF_ETF_VOO_202608.xlsx

Sheet Analysis
A1: 📈 ETF ANALYSIS — METRICS & SIGNALS
A2: Signals calculate automatically from Input_Data. Update yellow cells to refresh.
A3: 🟢 GOOD 🟡 REVIEW 🔴 ALERT ⚪ N/A Note: for ETFs, cost (expense ratio) and index fidelity (tracking difference) matter more than past returns.
A4: METRIC | B4: ETF | C4: VS BENCHMARK | D4: INTERPRETATION | E4: SIGNAL
A5: ── COST & EFFICIENCY ──
A6: Expense Ratio (Annual fee) | B6: =IFERROR(Input_Data!B14,"⚪ N/A") -> 0 | C6: =IFERROR(Input_Data!C14,"⚪ N/A") -> 0 | D6: Lower = better. <0.10% excellent · 0.10-0.50% good · >0.50% expensive for a passive ETF. | E6: =IFERROR(IF(Input_Data!B14<0.001,"🟢 GOOD",IF(Input_Data!B14<0.005,"🟡 REVIEW","🔴 ALERT")),"⚪ N/A") -> 🟢 GOOD
A7: Tracking Difference (Index fidelity) | B7: =IFERROR(Input_Data!B26,"⚪ N/A") -> 0 | C7: =IFERROR(Input_Data!C26,"⚪ N/A") -> 0 | D7: Lower = more faithful to the index. <0.10% excellent · >0.50% alert. | E7: =IFERROR(IF(Input_Data!B26<0.001,"🟢 GOOD",IF(Input_Data!B26<0.005,"🟡 REVIEW","🔴 ALERT")),"⚪ N/A") -> 🟢 GOOD
A8: ── PERFORMANCE ──
A9: 1-Year Return | B9: =IFERROR(Input_Data!B21,"⚪ N/A") -> 0 | C9: =IFERROR(Input_Data!B25,"⚪ N/A") -> 0 | D9: Compare vs 1-year benchmark (col 3). BEATS = ETF outperformed its index. IN LINE = <2% diff. LAGS = below index. | E9: =IFERROR(IF(Input_Data!B21>Input_Data!C21,"🟢 BEATS",IF(Input_Data!B21>Input_Data!C21*0.98,"🟡 IN LINE","🔴 LAGS")),"⚪ N/A") -> 🔴 LAGS
A10: 3-Year Annualized | B10: =IFERROR(Input_Data!B22,"⚪ N/A") -> 0 | C10: N/A | D10: >10% annualised over 3 years is solid for equity. Compare vs similar benchmarks. | E10: =IFERROR(IF(Input_Data!B22>0.1,"🟢 GOOD",IF(Input_Data!B22>0.05,"🟡 REVIEW","🔴 ALERT")),"⚪ N/A") -> 🔴 ALERT
A11: 5-Year Annualized | B11: =IFERROR(Input_Data!B23,"⚪ N/A") -> 0 | C11: N/D | D11: Most representative horizon for long-term ETF investors. | E11: =IFERROR(IF(Input_Data!B23>0.1,"🟢 GOOD",IF(Input_Data!B23>0.06,"🟡 REVIEW","🔴 ALERT")),"⚪ N/A") -> 🔴 ALERT
A12: ── INCOME & LIQUIDITY ──
A13: Dividend Yield | B13: =IFERROR(Input_Data!B29,"⚪ N/A") -> 0 | C13: =IFERROR(Input_Data!C29,"⚪ N/A") -> 0 | D13: 1-3% typical for equity ETFs. >4% for bond ETFs. Depends on fund objective. | E13: =IFERROR(IF(Input_Data!B29>0.02,"🟢 GOOD",IF(Input_Data!B29>0,"🟡 REVIEW","⚪ SIN DIV")),"⚪ N/A") -> ⚪ SIN DIV
A14: AUM (USD billions) | B14: =IFERROR(Input_Data!B15,"⚪ N/A") -> 0 | C14: =IFERROR(Input_Data!C15,"⚪ N/A") -> 0 | D14: >1B USD = sufficient liquidity. <100M USD = closure risk. | E14: =IFERROR(IF(Input_Data!B15>1,"🟢 GOOD",IF(Input_Data!B15>0.1,"🟡 REVIEW","🔴 ALERT")),"⚪ N/A") -> 🔴 ALERT
A15: Beta vs S&P 500 | B15: =IFERROR(Input_Data!B27,"⚪ N/A") -> 0 | C15: =IFERROR(Input_Data!C27,"⚪ N/A") -> 0 | D15: 1.0 = moves like S&P. >1.2 more volatile · <0.8 more defensive. | E15: =IFERROR(IF(Input_Data!B27<1.2,"🟡 NORMAL","🟡 REVIEW"),"⚪ N/A") -> 🟡 NORMAL
A17: ⚠️ For ETFs, expense ratio and tracking difference matter more than past returns. A cheap, index-faithful ETF typically wins over the long run.

Sheet My_Position
A1: 📊 MY POSITION IN [TICKER] — Personal Analysis
A2: 🟡 YELLOW = update manually · 🔵 BLUE = auto-calculated · Fill both markets if applicable (e.g. EUR→USD and direct USD), or only one.
A3: 🛒 MY PURCHASES
A4: FIELD | B4: MARKET 1 (e.g. EUR→USD or local currency) | C4: MARKET 2 (e.g. direct USD) | D4: TOTAL / COMBINED | E4: NOTES
A5: Number of shares purchased
A6: Avg purchase price (local currency) → From your broker transaction history
A7: Purchase currency
A8: FX rate at time of purchase (local/USD) → Use EUR/USD, MXN/USD, or 1 if already USD
A9: Purchase date (approximate)
A10: 💹 CURRENT PRICE (update each time you analyse)
A11: FIELD | B11: MARKET 1 | C11: MARKET 2
A12: Current price per share (local currency) → stockanalysis.com/etf/voo → live price
A13: Current FX rate (local/USD) → Google "EUR USD rate" or XE.com
A14: Price date
A15: 📈 POSITION ANALYSIS (auto-calculated)
A16: FIELD | B16: MARKET 1 | C16: MARKET 2 | D16: TOTAL (USD) | E16: NOTES
A17: Total purchase cost (local currency) | B17: =B5*B6 -> 0 | C17: =C5*C6 -> 0 | D17: =IFERROR(B17/B8+C17/C8,"—") -> — | E17: Combined total in USD
A18: Total cost in local currency | B18: =B17 -> 0 | C18: =C17*C8 -> 0 | D18: =B18+C18 -> 0 | E18: Market 1 in local currency · Market 2 converted at purchase FX rate
A19: Current value (local currency) | B19: =B5*B12 -> 0 | C19: =C5*C12 -> 0 | D19: =IFERROR(B19/B13+C19/C13,"—") -> — | E19: Combined total in USD
A20: Current value in local currency | B20: =B19 -> 0 | C20: =C19*C13 -> 0 | D20: =B20+C20 -> 0 | E20: Market 1 in local currency · Market 2 at current FX rate
A21: Gain / Loss (local currency) | B21: =B20-B18 -> 0 | C21: =C20-C18 -> 0 | D21: =D20-D18 -> 0 | E21: Positive = unrealised gain · Negative = unrealised loss
A22: Return (%) | B22: =IFERROR(B21/B18,"N/D") -> N/D | C22: =IFERROR(C21/C18,"N/D") -> N/D | D22: =IFERROR(D21/D18,"N/D") -> N/D | E22: Return on initial investment
A23: FX Effect (local currency) | B23: N/A | C23: =C5*C12*(C13-C8) -> 0 | D23: =C23 -> 0 | E23: How much you gained/lost purely from currency movement
A24: ⏱️ RULE OF 72 & PROJECTIONS (based on historical returns)
A25: SCENARIO | B25: RATE USED | C25: YEARS TO DOUBLE | D25: VALUE IN 5 YEARS | E25: VALUE IN 10 YEARS
A26: 5-Year annualized return (historical) | B26: =Input_Data!B23 -> 0 | C26: =IFERROR(72/(B26*100),"N/D") -> N/D | D26: =IFERROR(My_Position!D20*(1+B26)^5,"N/D") -> 0 | E26: =IFERROR(My_Position!D20*(1+B26)^10,"N/D") -> 0
A27: 10-Year annualized return (historical) | B27: =Input_Data!B24 -> 0 | C27: =IFERROR(72/(B27*100),"N/D") -> N/D | D27: =IFERROR(My_Position!D20*(1+B27)^5,"N/D") -> 0 | E27: =IFERROR(My_Position!D20*(1+B27)^10,"N/D") -> 0
A28: 1-Year return (most recent) | B28: =Input_Data!B21 -> 0 | C28: =IFERROR(72/(B28*100),"N/D") -> N/D | D28: =IFERROR(My_Position!D20*(1+B28)^5,"N/D") -> 0 | E28: =IFERROR(My_Position!D20*(1+B28)^10,"N/D") -> 0
A29: Conservative scenario (7%/yr) | B29: 0.07 | C29: =IFERROR(72/(B29*100),"N/D") -> 10.285714 | D29: =IFERROR(My_Position!D20*(1+B29)^5,"N/D") -> 0 | E29: =IFERROR(My_Position!D20*(1+B29)^10,"N/D") -> 0
A30: 🎯 BREAK-EVEN & VALUATION
A31: METRIC | B31: VALUE | C31: INTERPRETATION
A32: Break-even price — Market 1 (local currency) | B32: =B6 -> 0 | C32: You are in profit if current price > this
A33: Break-even price — Market 2 (USD) | B33: 609.22 | C33: You are in profit if current price > this
A34: Have I recouped my investment? (Market 1) | B34: =IF(B12>B6,"✅ YES — you are in profit","❌ NO — still at a loss") -> ❌ NO — still at a loss | C34: Compares current price vs purchase price
A35: Have I recouped my investment? (Market 2) | B35: =IF(C12>C6,"✅ YES — you are in profit","❌ NO — still at a loss") -> ❌ NO — still at a loss | C35: Compares current price vs purchase price
A36: S&P 500 P/E Ratio (is the market expensive?) → stockanalysis.com/etf/voo → "PE Ratio" | C36: <17x cheap historically · 17-25x fair · >25x expensive
A37: ETF NAV (net asset value) → stockanalysis.com/etf/voo → "NAV" | C37: If price > NAV the ETF trades at a premium.
A38: Premium / Discount vs NAV (%) | B38: =IFERROR((C12-B37)/B37,"N/D") -> N/D | C38: < 0.10% normal for large ETFs. > 0.50% means you are paying significantly above NAV.
A40: 🟡 YELLOW = update manually | 🔵 BLUE = auto-calculated | Update price and FX rate each time you analyse.
A41: 📌 Rule of 72: divide 72 by the annual rate (%) to find how many years your money doubles. E.g.: 10% → 72/10 = 7.2 years.
...

Sheet Guide
A1: 📖 USER GUIDE — AF_ETF Template
A2: STEP | B2: WHAT TO DO
A3: 1. Identify the ETF | B3: Enter ticker, name, tracked index and issuer in Input_Data.
A4: 2. Yahoo Finance | B4: Search ticker → Statistics: Expense Ratio, Beta, Yield, AUM, Volume.
A5: 3. Issuer site | B5: Vanguard (vanguard.com) · iShares (ishares.com) · SPDR (ssga.com) Official returns, 30-Day SEC Yield, and distributions.
A6: 4. ETF.com | B6: etf.com → search ticker → Tracking Difference and competitor comparisons.
A7: 5. Read Analysis | B7: Signals evaluate cost, performance and liquidity. For ETFs, cost beats past returns.
A8: 6. Save | B8: AF_ETF_TICKER_YYYYMM.xlsx e.g.: AF_ETF_VOO_202608.xlsx
A10: WHAT MATTERS MOST IN AN ETF
A11: Expense Ratio | B11: As low as possible. VOO charges 0.03% — a benchmark of excellence.
A12: Tracking Difference | B12: How faithfully it replicates the index. Lower = better.
A13: AUM | B13: Larger funds are more liquid and harder to close.
A14: Performance | B14: Always compare vs the benchmark, never in isolation.
A15: Diversification | B15: How many holdings? Is it concentrated in a few companies?
A17: YOUR CURRENT ETFs | B17: TICKER → INDEX / SECTOR
A18: VOO | B18: S&P 500 (broad US market) — Vanguard
A19: XLE | B19: Energy Select Sector — SPDR
A20: XLI | B20: Industrials Select Sector — SPDR
A21: EWL | B21: Switzerland — iShares (MSCI Switzerland)
A22: EWQ | B22: France — iShares (MSCI France)
A23: EWU | B23: United Kingdom — iShares (MSCI UK)
... A25: MCHI | B25: China — iShares (MSCI China)
